<sdf version="1.6">
    <model name="onshape">
        <link name="body">
            <visual name="body_0_body_visual">
                <pose>0 0 0 0 -0 0</pose>
                <geometry>
                    <mesh>
                        <uri>body.obj</uri>
                    </mesh>
                </geometry>
                <material>
                    <ambient>0.80000000000000004441 0.80000000000000004441 0.80000000000000004441 1</ambient>
                    <diffuse>0.80000000000000004441 0.80000000000000004441 0.80000000000000004441 1</diffuse>
                    <specular>0.1 0.1 0.1 1</specular>
                    <emissive>0 0 0 0</emissive>
                </material>
            </visual>
            <collision name="body_0_body_visual">
                <pose>0 0 0 0 -0 0</pose>
                <geometry>
                    <mesh>
                        <uri>/body.obj</uri>
                    </mesh>
                </geometry>
            </collision>
            <visual name="body_1_wheel_visual">
                <pose>0 0 0 0 -0 0</pose>
                <geometry>
                    <mesh>
                        <uri>wheel.obj</uri>
                    </mesh>
                </geometry>
                <material>
                    <ambient>0.26274509803921569651 0.28235294117647058432 0.30196078431372547213 1</ambient>
                    <diffuse>0.26274509803921569651 0.28235294117647058432 0.30196078431372547213 1</diffuse>
                    <specular>0.1 0.1 0.1 1</specular>
                    <emissive>0 0 0 0</emissive>
                </material>
            </visual>
            <collision name="body_1_wheel_visual">
                <pose>0 0 0 0 -0 0</pose>
                <geometry>
                    <mesh>
                        <uri>/wheel.obj</uri>
                    </mesh>
                </geometry>
            </collision>
            <inertial>
                <pose>0.030528834671778498633 0.026311528874656694987 0.022846745772597824159 0 0 0</pose>
                <mass>2.5741640170587927194</mass>
                <inertia>
                    <ixx>0.00242208258841036762</ixx>
                    <ixy>0.00011105211725562187186</ixy>
                    <ixz>3.8640056771370586645e-05</ixz>
                    <iyy>0.0025180176561021283543</iyy>
                    <iyz>-0.0002927496853081748172</iyz>
                    <izz>0.0035676303507577843827</izz>
                </inertia>
            </inertial>
        </link>

        <link name="wheel">
            <visual name="wheel_0_wheel_visual">
                <pose>0.10699999999999999789 0 -3.4694469519536141888e-18 0 -0 0</pose>
                <geometry>
                    <mesh>
                        <uri>wheel.obj</uri>
                    </mesh>
                </geometry>
                <material>
                    <ambient>0.26274509803921569651 0.28235294117647058432 0.30196078431372547213 1</ambient>
                    <diffuse>0.26274509803921569651 0.28235294117647058432 0.30196078431372547213 1</diffuse>
                    <specular>0.1 0.1 0.1 1</specular>
                    <emissive>0 0 0 0</emissive>
                </material>
            </visual>
            <collision name="wheel_0_wheel_visual">
                <pose>0.10699999999999999789 0 -3.4694469519536141888e-18 0 -0 0</pose>
                <geometry>
                    <mesh>
                        <uri>/wheel.obj</uri>
                    </mesh>
                </geometry>
            </collision>
            <inertial>
                <pose>0.090999999999999997558 0.03250000000000000111 0.024999999999999990979 0 0 0</pose>
                <mass>0.33541920259867769039</mass>
                <inertia>
                    <ixx>0.00034529842223087294558</ixx>
                    <ixy>0</ixy>
                    <ixz>0</ixz>
                    <iyy>0.00017436687051762195309</iyy>
                    <iyz>0</iyz>
                    <izz>0.00017436687051762189888</izz>
                </inertia>
            </inertial>
        </link>

        <joint name="wheel2_speed" type="revolute">
            <pose>0.09500000000000000111 0.032499999999999994171 0.024999999999999994449
                -1.570796326794896558 -0 1.570796326794896558</pose>
            <parent>body</parent>
            <child>wheel</child>
            <axis>
                <xyz>0 0 1</xyz>
                <limit>
                    <effort>1</effort>
                    <velocity>20</velocity>
                </limit>
            </axis>
        </joint>


    </model>
</sdf>