<robot name="onshape">
<link name="body">
<visual>
<origin xyz="0 0 0" rpy="0 -0 0" />
<geometry>
<mesh filename="package:///body.stl"/>
</geometry>
<material name="body_material">
<color rgba="0.80000000000000004441 0.80000000000000004441 0.80000000000000004441 1.0"/>
</material>
</visual>
<collision>
<origin xyz="0 0 0" rpy="0 -0 0" />
<geometry>
<mesh filename="package:///body.stl"/>
</geometry>
</collision>
<inertial>
<origin xyz="0.037500001962775565689 0.025384343231719466716 0.022524135168976326671" rpy="0 0 0"/>
<mass value="2.2387448144601145295" />
<inertia ixx="0.0020602257937801186222" ixy="4.4849745953757699221e-10"  ixz="6.4700580511978857279e-11" iyy="0.0015069060220098920867" iyz="-0.00028761045332653640367" izz="0.0025435366954410995599" />
</inertial>
</link>

<link name="wheel">
<visual>
<origin xyz="-0.03250000000000000111 0.024999999999999997918 -0.020000000000000000416" rpy="1.570796326794896558 1.570796326794896558 0" />
<geometry>
<mesh filename="package:///wheel.stl"/>
</geometry>
<material name="wheel_material">
<color rgba="0.26274509803921569651 0.28235294117647058432 0.30196078431372547213 1.0"/>
</material>
</visual>
<collision>
<origin xyz="-0.03250000000000000111 0.024999999999999997918 -0.020000000000000000416" rpy="1.570796326794896558 1.570796326794896558 0" />
<geometry>
<mesh filename="package:///wheel.stl"/>
</geometry>
</collision>
<inertial>
<origin xyz="0 3.4694469519536141888e-18 -0.0040000000000000000833" rpy="0 0 0"/>
<mass value="0.3354192025986777459" />
<inertia ixx="0.00017436687051762192599" ixy="0"  ixz="0" iyy="0.00017436687051762189888" iyz="0" izz="0.00034529842223087289137" />
</inertial>
</link>

<joint name="wheel1_speed" type="fixed">
<origin xyz="-0.020000000000000000416 0.03250000000000000111 0.024999999999999997918" rpy="-1.570796326794896558 -0 1.570796326794896558" />
<parent link="body" />
<child link="wheel" />
<axis xyz="0 0 1"/>
<limit effort="1" velocity="20" />
<joint_properties friction="0.0"/>
</joint>

<link name="wheel_2">
<visual>
<origin xyz="-0.032499999999999994171 0.024999999999999997918 -0.01199999999999999678" rpy="1.570796326794896558 1.570796326794896558 0" />
<geometry>
<mesh filename="package:///wheel.stl"/>
</geometry>
<material name="wheel_material">
<color rgba="0.26274509803921569651 0.28235294117647058432 0.30196078431372547213 1.0"/>
</material>
</visual>
<collision>
<origin xyz="-0.032499999999999994171 0.024999999999999997918 -0.01199999999999999678" rpy="1.570796326794896558 1.570796326794896558 0" />
<geometry>
<mesh filename="package:///wheel.stl"/>
</geometry>
</collision>
<inertial>
<origin xyz="6.9388939039072283776e-18 3.4694469519536141888e-18 0.0040000000000000035527" rpy="0 0 0"/>
<mass value="0.3354192025986777459" />
<inertia ixx="0.00017436687051762192599" ixy="0"  ixz="0" iyy="0.00017436687051762189888" iyz="0" izz="0.00034529842223087289137" />
</inertial>
</link>

<joint name="wheel2_speed" type="revolute">
<origin xyz="0.09500000000000000111 0.032499999999999994171 0.024999999999999994449" rpy="-1.570796326794896558 -0 1.570796326794896558" />
<parent link="body" />
<child link="wheel_2" />
<axis xyz="0 0 1"/>
<limit effort="1" velocity="20" />
<joint_properties friction="0.0"/>
</joint>


</robot>
