<robot name="onshape">
<link name="body">
<visual>
<origin xyz="-0.32717104504557964484 0.11870586107737114701 0.26461932979901653384" rpy="3.1315712011710048479 9.08699813932780043e-05 0.018134783422132497166" />
<geometry>
<mesh filename="package:///m3_bolt.stl"/>
</geometry>
<material name="m3_bolt_material">
<color rgba="0.74509803921568629193 0.73725490196078435901 0.72941176470588231506 1.0"/>
</material>
</visual>
<collision>
<origin xyz="-0.32717104504557964484 0.11870586107737114701 0.26461932979901653384" rpy="3.1315712011710048479 9.08699813932780043e-05 0.018134783422132497166" />
<geometry>
<mesh filename="package:///m3_bolt.stl"/>
</geometry>
</collision>
<visual>
<origin xyz="-0.1912510146677121603 0.12694116959264220568 0.24154799433537210707" rpy="-1.5617288774461293155 -1.5607744624144965773 1.5798641161966702207" />
<geometry>
<mesh filename="package:///side_plate.stl"/>
</geometry>
<material name="side_plate_material">
<color rgba="0.21960784313725489891 0.18039215686274509554 0.12549019607843137081 1.0"/>
</material>
</visual>
<collision>
<origin xyz="-0.1912510146677121603 0.12694116959264220568 0.24154799433537210707" rpy="-1.5617288774461293155 -1.5607744624144965773 1.5798641161966702207" />
<geometry>
<mesh filename="package:///side_plate.stl"/>
</geometry>
</collision>
<visual>
<origin xyz="-0.18870301769261302316 0.1492584036301935202 0.25682534670081674788" rpy="1.5607748743761082899 9.08699813932780043e-05 0.018134783422132497166" />
<geometry>
<mesh filename="package:///tail_fin.stl"/>
</geometry>
<material name="tail_fin_material">
<color rgba="0.21960784313725489891 0.18039215686274509554 0.12549019607843137081 1.0"/>
</material>
</visual>
<collision>
<origin xyz="-0.18870301769261302316 0.1492584036301935202 0.25682534670081674788" rpy="1.5607748743761082899 9.08699813932780043e-05 0.018134783422132497166" />
<geometry>
<mesh filename="package:///tail_fin.stl"/>
</geometry>
</collision>
<visual>
<origin xyz="-0.19842472495512569752 0.13368156316712478948 0.22847913873580660837" rpy="1.5607748743761082899 9.08699813932780043e-05 0.018134783422132497166" />
<geometry>
<mesh filename="package:///m5-nut-4mm.stl"/>
</geometry>
<material name="m5-nut-4mm_material">
<color rgba="0.74509803921568629193 0.73725490196078435901 0.72941176470588231506 1.0"/>
</material>
</visual>
<collision>
<origin xyz="-0.19842472495512569752 0.13368156316712478948 0.22847913873580660837" rpy="1.5607748743761082899 9.08699813932780043e-05 0.018134783422132497166" />
<geometry>
<mesh filename="package:///m5-nut-4mm.stl"/>
</geometry>
</collision>
<visual>
<origin xyz="-0.29417483567318958304 0.11912389300350534338 0.24661723502195992408" rpy="3.1315712011710048479 9.08699813932780043e-05 0.018134783422132497166" />
<geometry>
<mesh filename="package:///m3_bolt.stl"/>
</geometry>
<material name="m3_bolt_material">
<color rgba="0.74509803921568629193 0.73725490196078435901 0.72941176470588231506 1.0"/>
</material>
</visual>
<collision>
<origin xyz="-0.29417483567318958304 0.11912389300350534338 0.24661723502195992408" rpy="3.1315712011710048479 9.08699813932780043e-05 0.018134783422132497166" />
<geometry>
<mesh filename="package:///m3_bolt.stl"/>
</geometry>
</collision>
<visual>
<origin xyz="-0.29555300366361558773 0.19510757935506509164 0.24585561738957328881" rpy="-0.010021452418788408603 9.08699813932780043e-05 0.018134783422132497166" />
<geometry>
<mesh filename="package:///m3_bolt.stl"/>
</geometry>
<material name="m3_bolt_material">
<color rgba="0.74509803921568629193 0.73725490196078435901 0.72941176470588231506 1.0"/>
</material>
</visual>
<collision>
<origin xyz="-0.29555300366361558773 0.19510757935506509164 0.24585561738957328881" rpy="-0.010021452418788408603 9.08699813932780043e-05 0.018134783422132497166" />
<geometry>
<mesh filename="package:///m3_bolt.stl"/>
</geometry>
</collision>
<visual>
<origin xyz="-0.32854921303600559401 0.19468954742893088139 0.2638577121666300096" rpy="-0.010021452418788405134 9.08699813932780043e-05 0.018134783422132497166" />
<geometry>
<mesh filename="package:///m3_bolt.stl"/>
</geometry>
<material name="m3_bolt_material">
<color rgba="0.74509803921568629193 0.73725490196078435901 0.72941176470588231506 1.0"/>
</material>
</visual>
<collision>
<origin xyz="-0.32854921303600559401 0.19468954742893088139 0.2638577121666300096" rpy="-0.010021452418788405134 9.08699813932780043e-05 0.018134783422132497166" />
<geometry>
<mesh filename="package:///m3_bolt.stl"/>
</geometry>
</collision>
<visual>
<origin xyz="-0.3098181751089727487 0.12693129360365140723 0.25553802126341368384" rpy="-1.5617288774461286494 -1.5607744624144965773 1.5798641161966706647" />
<geometry>
<mesh filename="package:///jgy-370gearbox.stl"/>
</geometry>
<material name="jgy-370gearbox_material">
<color rgba="0.96078431372549022438 0.96078431372549022438 0.96470588235294119084 1.0"/>
</material>
</visual>
<collision>
<origin xyz="-0.3098181751089727487 0.12693129360365140723 0.25553802126341368384" rpy="-1.5617288774461286494 -1.5607744624144965773 1.5798641161966706647" />
<geometry>
<mesh filename="package:///jgy-370gearbox.stl"/>
</geometry>
</collision>
<visual>
<origin xyz="-0.18951930382706064226 0.19439117123334689885 0.28187424116081860603" rpy="1.5707054522502985616 -0.01002145237741168364 -1.5526606326930840751" />
<geometry>
<mesh filename="package:///bottom_plate.stl"/>
</geometry>
<material name="bottom_plate_material">
<color rgba="0.21960784313725489891 0.18039215686274509554 0.12549019607843137081 1.0"/>
</material>
</visual>
<collision>
<origin xyz="-0.18951930382706064226 0.19439117123334689885 0.28187424116081860603" rpy="1.5707054522502985616 -0.01002145237741168364 -1.5526606326930840751" />
<geometry>
<mesh filename="package:///bottom_plate.stl"/>
</geometry>
</collision>
<visual>
<origin xyz="-0.18891026675496855325 0.16072686648079559379 0.26509767452740284899" rpy="-0.010021452418788405134 9.08699813932780043e-05 0.018134783422132497166" />
<geometry>
<mesh filename="package:///tail_fin.stl"/>
</geometry>
<material name="tail_fin_material">
<color rgba="0.21960784313725489891 0.18039215686274509554 0.12549019607843137081 1.0"/>
</material>
</visual>
<collision>
<origin xyz="-0.18891026675496855325 0.16072686648079559379 0.26509767452740284899" rpy="-0.010021452418788405134 9.08699813932780043e-05 0.018134783422132497166" />
<geometry>
<mesh filename="package:///tail_fin.stl"/>
</geometry>
</collision>
<visual>
<origin xyz="-0.19843008648507878822 0.13427281895886489238 0.28747617584651868894" rpy="1.5607748743761082899 9.08699813932780043e-05 0.018134783422132497166" />
<geometry>
<mesh filename="package:///m5-bolt-long.stl"/>
</geometry>
<material name="m5-bolt-long_material">
<color rgba="0.74509803921568629193 0.73725490196078435901 0.72941176470588231506 1.0"/>
</material>
</visual>
<collision>
<origin xyz="-0.19843008648507878822 0.13427281895886489238 0.28747617584651868894" rpy="1.5607748743761082899 9.08699813932780043e-05 0.018134783422132497166" />
<geometry>
<mesh filename="package:///m5-bolt-long.stl"/>
</geometry>
</collision>
<visual>
<origin xyz="-0.32716940932457694302 0.11852547795446737033 0.24662023373134173143" rpy="3.1315712011710048479 9.08699813932780043e-05 0.018134783422132497166" />
<geometry>
<mesh filename="package:///m3_bolt.stl"/>
</geometry>
<material name="m3_bolt_material">
<color rgba="0.74509803921568629193 0.73725490196078435901 0.72941176470588231506 1.0"/>
</material>
</visual>
<collision>
<origin xyz="-0.32716940932457694302 0.11852547795446737033 0.24662023373134173143" rpy="3.1315712011710048479 9.08699813932780043e-05 0.018134783422132497166" />
<geometry>
<mesh filename="package:///m3_bolt.stl"/>
</geometry>
</collision>
<visual>
<origin xyz="-0.29417647139419217384 0.11930427612640910617 0.26461633108963472649" rpy="3.1315712011710048479 9.08699813932780043e-05 0.018134783422132497166" />
<geometry>
<mesh filename="package:///m3_bolt.stl"/>
</geometry>
<material name="m3_bolt_material">
<color rgba="0.74509803921568629193 0.73725490196078435901 0.72941176470588231506 1.0"/>
</material>
</visual>
<collision>
<origin xyz="-0.29417647139419217384 0.11930427612640910617 0.26461633108963472649" rpy="3.1315712011710048479 9.08699813932780043e-05 0.018134783422132497166" />
<geometry>
<mesh filename="package:///m3_bolt.stl"/>
</geometry>
</collision>
<visual>
<origin xyz="-0.19933141442251117725 0.18367083050367721819 0.22797807450397331031" rpy="1.5607748743761082899 9.08699813932780043e-05 0.018134783422132497166" />
<geometry>
<mesh filename="package:///m5-nut-4mm.stl"/>
</geometry>
<material name="m5-nut-4mm_material">
<color rgba="0.74509803921568629193 0.73725490196078435901 0.72941176470588231506 1.0"/>
</material>
</visual>
<collision>
<origin xyz="-0.19933141442251117725 0.18367083050367721819 0.22797807450397331031" rpy="1.5607748743761082899 9.08699813932780043e-05 0.018134783422132497166" />
<geometry>
<mesh filename="package:///m5-nut-4mm.stl"/>
</geometry>
</collision>
<visual>
<origin xyz="-0.18906131754433674885 0.16899781521603840506 0.25362733928042707765" rpy="-1.5808177792136850481 9.0869981393277841669e-05 0.018134783422132479819" />
<geometry>
<mesh filename="package:///tail_fin.stl"/>
</geometry>
<material name="tail_fin_material">
<color rgba="0.21960784313725489891 0.18039215686274509554 0.12549019607843137081 1.0"/>
</material>
</visual>
<collision>
<origin xyz="-0.18906131754433674885 0.16899781521603840506 0.25362733928042707765" rpy="-1.5808177792136850481 9.0869981393277841669e-05 0.018134783422132479819" />
<geometry>
<mesh filename="package:///tail_fin.stl"/>
</geometry>
</collision>
<visual>
<origin xyz="-0.18885406848198127427 0.15752935236543633146 0.24535501145384081001" rpy="3.1315712011710048479 9.0869981393277841669e-05 0.018134783422132479819" />
<geometry>
<mesh filename="package:///tail_fin.stl"/>
</geometry>
<material name="tail_fin_material">
<color rgba="0.21960784313725489891 0.18039215686274509554 0.12549019607843137081 1.0"/>
</material>
</visual>
<collision>
<origin xyz="-0.18885406848198127427 0.15752935236543633146 0.24535501145384081001" rpy="3.1315712011710048479 9.0869981393277841669e-05 0.018134783422132479819" />
<geometry>
<mesh filename="package:///tail_fin.stl"/>
</geometry>
</collision>
<visual>
<origin xyz="-0.31031591240771017048 0.13830356675162694402 0.27160681819678428317" rpy="-1.5707054522502985616 0.01002145237741168711 1.588932020896709485" />
<geometry>
<mesh filename="package:///jgy-37012v_dc_motor.stl"/>
</geometry>
<material name="jgy-37012v_dc_motor_material">
<color rgba="0.97254901960784312376 0.9686274509803921573 0.92941176470588238168 1.0"/>
</material>
</visual>
<collision>
<origin xyz="-0.31031591240771017048 0.13830356675162694402 0.27160681819678428317" rpy="-1.5707054522502985616 0.01002145237741168711 1.588932020896709485" />
<geometry>
<mesh filename="package:///jgy-37012v_dc_motor.stl"/>
</geometry>
</collision>
<visual>
<origin xyz="-0.32854757731500300322 0.19450916430602710472 0.24585861609895515167" rpy="-0.010021452418788412073 9.08699813932780043e-05 0.018134783422132497166" />
<geometry>
<mesh filename="package:///m3_bolt.stl"/>
</geometry>
<material name="m3_bolt_material">
<color rgba="0.74509803921568629193 0.73725490196078435901 0.72941176470588231506 1.0"/>
</material>
</visual>
<collision>
<origin xyz="-0.32854757731500300322 0.19450916430602710472 0.24585861609895515167" rpy="-0.010021452418788412073 9.08699813932780043e-05 0.018134783422132497166" />
<geometry>
<mesh filename="package:///m3_bolt.stl"/>
</geometry>
</collision>
<visual>
<origin xyz="-0.1993367759524642957 0.18426208629541734885 0.28697511161468541863" rpy="1.5607748743761082899 9.08699813932780043e-05 0.018134783422132497166" />
<geometry>
<mesh filename="package:///m5-bolt-long.stl"/>
</geometry>
<material name="m5-bolt-long_material">
<color rgba="0.74509803921568629193 0.73725490196078435901 0.72941176470588231506 1.0"/>
</material>
</visual>
<collision>
<origin xyz="-0.1993367759524642957 0.18426208629541734885 0.28697511161468541863" rpy="1.5607748743761082899 9.08699813932780043e-05 0.018134783422132497166" />
<geometry>
<mesh filename="package:///m5-bolt-long.stl"/>
</geometry>
</collision>
<visual>
<origin xyz="-0.31186485008564351906 0.15721833442892019228 0.28723591203848536368" rpy="1.5607748743761082899 9.08699813932780043e-05 0.018134783422132497166" />
<geometry>
<mesh filename="package:///m5-bolt-long.stl"/>
</geometry>
<material name="m5-bolt-long_material">
<color rgba="0.74509803921568629193 0.73725490196078435901 0.72941176470588231506 1.0"/>
</material>
</visual>
<collision>
<origin xyz="-0.31186485008564351906 0.15721833442892019228 0.28723591203848536368" rpy="1.5607748743761082899 9.08699813932780043e-05 0.018134783422132497166" />
<geometry>
<mesh filename="package:///m5-bolt-long.stl"/>
</geometry>
</collision>
<visual>
<origin xyz="-0.31090620246983535768 0.18691841440751433279 0.25493674418521367064" rpy="1.5617288774461293155 1.5607744624144965773 -1.5617285373931231174" />
<geometry>
<mesh filename="package:///jgy-370gearbox.stl"/>
</geometry>
<material name="jgy-370gearbox_material">
<color rgba="0.96078431372549022438 0.96078431372549022438 0.96470588235294119084 1.0"/>
</material>
</visual>
<collision>
<origin xyz="-0.31090620246983535768 0.18691841440751433279 0.25493674418521367064" rpy="1.5617288774461293155 1.5607744624144965773 -1.5617285373931231174" />
<geometry>
<mesh filename="package:///jgy-370gearbox.stl"/>
</geometry>
</collision>
<visual>
<origin xyz="-0.19188167431405558916 0.15907370805502157873 0.25522661560056564278" rpy="3.1325252042410260955 1.5607744624144965773 -1.5617285373931235615" />
<geometry>
<mesh filename="package:///tail.stl"/>
</geometry>
<material name="tail_material">
<color rgba="0.92156862745098033773 0.92156862745098033773 0.92156862745098033773 1.0"/>
</material>
</visual>
<collision>
<origin xyz="-0.19188167431405558916 0.15907370805502157873 0.25522661560056564278" rpy="3.1325252042410260955 1.5607744624144965773 -1.5617285373931235615" />
<geometry>
<mesh filename="package:///tail.stl"/>
</geometry>
</collision>
<visual>
<origin xyz="-0.1924141216408586097 0.19120802775239073568 0.26890522600167526823" rpy="1.5617288774461293155 1.5607744624144965773 -1.5617285373931231174" />
<geometry>
<mesh filename="package:///side_plate.stl"/>
</geometry>
<material name="side_plate_material">
<color rgba="0.21960784313725489891 0.18039215686274509554 0.12549019607843137081 1.0"/>
</material>
</visual>
<collision>
<origin xyz="-0.1924141216408586097 0.19120802775239073568 0.26890522600167526823" rpy="1.5617288774461293155 1.5607744624144965773 -1.5617285373931231174" />
<geometry>
<mesh filename="package:///side_plate.stl"/>
</geometry>
</collision>
<visual>
<origin xyz="-0.31185948855569040061 0.15662707863718008938 0.22823887492777328312" rpy="1.5607748743761082899 9.08699813932780043e-05 0.018134783422132497166" />
<geometry>
<mesh filename="package:///m5-nut-4mm.stl"/>
</geometry>
<material name="m5-nut-4mm_material">
<color rgba="0.74509803921568629193 0.73725490196078435901 0.72941176470588231506 1.0"/>
</material>
</visual>
<collision>
<origin xyz="-0.31185948855569040061 0.15662707863718008938 0.22823887492777328312" rpy="1.5607748743761082899 9.08699813932780043e-05 0.018134783422132497166" />
<geometry>
<mesh filename="package:///m5-nut-4mm.stl"/>
</geometry>
</collision>
<visual>
<origin xyz="-0.31099415528504498196 0.17553551873166639563 0.23886800048224543502" rpy="1.5707054522502985616 -0.010021452377411681905 -1.5526606326930840751" />
<geometry>
<mesh filename="package:///jgy-37012v_dc_motor.stl"/>
</geometry>
<material name="jgy-37012v_dc_motor_material">
<color rgba="0.97254901960784312376 0.9686274509803921573 0.92941176470588238168 1.0"/>
</material>
</visual>
<collision>
<origin xyz="-0.31099415528504498196 0.17553551873166639563 0.23886800048224543502" rpy="1.5707054522502985616 -0.010021452377411681905 -1.5526606326930840751" />
<geometry>
<mesh filename="package:///jgy-37012v_dc_motor.stl"/>
</geometry>
</collision>
<visual>
<origin xyz="-0.29555463938461823403 0.19528796247796884056 0.26385471345724814674" rpy="-0.01002145241878839646 9.08699813932780043e-05 0.018134783422132497166" />
<geometry>
<mesh filename="package:///m3_bolt.stl"/>
</geometry>
<material name="m3_bolt_material">
<color rgba="0.74509803921568629193 0.73725490196078435901 0.72941176470588231506 1.0"/>
</material>
</visual>
<collision>
<origin xyz="-0.29555463938461823403 0.19528796247796884056 0.26385471345724814674" rpy="-0.01002145241878839646 9.08699813932780043e-05 0.018134783422132497166" />
<geometry>
<mesh filename="package:///m3_bolt.stl"/>
</geometry>
</collision>
<visual>
<origin xyz="-0.33527553348137617562 0.12422880045084888634 0.23156158626030950987" rpy="-9.087454459799094162e-05 -0.01002145237741168364 -1.5526606326930840751" />
<geometry>
<mesh filename="package:///front_plate.stl"/>
</geometry>
<material name="front_plate_material">
<color rgba="0.21960784313725489891 0.18039215686274509554 0.12549019607843137081 1.0"/>
</material>
</visual>
<collision>
<origin xyz="-0.33527553348137617562 0.12422880045084888634 0.23156158626030950987" rpy="-9.087454459799094162e-05 -0.01002145237741168364 -1.5526606326930840751" />
<geometry>
<mesh filename="package:///front_plate.stl"/>
</geometry>
</collision>
<visual>
<origin xyz="-0.19245977461184543555 0.19082632831987680899 0.23090713973529256031" rpy="9.087454459799094162e-05 0.01002145237741168364 1.5889320208967092629" />
<geometry>
<mesh filename="package:///back_plate.stl"/>
</geometry>
<material name="back_plate_material">
<color rgba="0.21960784313725489891 0.18039215686274509554 0.12549019607843137081 1.0"/>
</material>
</visual>
<collision>
<origin xyz="-0.19245977461184543555 0.19082632831987680899 0.23090713973529256031" rpy="9.087454459799094162e-05 0.01002145237741168364 1.5889320208967092629" />
<geometry>
<mesh filename="package:///back_plate.stl"/>
</geometry>
</collision>
<visual>
<origin xyz="-0.18951466928421983882 0.19388008571845288808 0.23087680230240648083" rpy="1.5707054522502985616 -0.01002145237741168364 -1.5526606326930840751" />
<geometry>
<mesh filename="package:///bottom_plate.stl"/>
</geometry>
<material name="bottom_plate_material">
<color rgba="0.21960784313725489891 0.18039215686274509554 0.12549019607843137081 1.0"/>
</material>
</visual>
<collision>
<origin xyz="-0.18951466928421983882 0.19388008571845288808 0.23087680230240648083" rpy="1.5707054522502985616 -0.01002145237741168364 -1.5526606326930840751" />
<geometry>
<mesh filename="package:///bottom_plate.stl"/>
</geometry>
</collision>
<inertial>
<origin xyz="-0.27876772091850815505 0.15750019565709050262 0.25527061929026106935" rpy="0 0 0"/>
<mass value="0.93999623980613211671" />
<inertia ixx="0.00048704164977702180811" ixy="-7.1556237764334998581e-05"  ixz="-1.3210036595590260439e-06" iyy="0.0044213736568990396475" iyz="1.1630040023786329965e-05" izz="0.0046747941085663767199" />
</inertial>
</link>

<link name="assembly_3">
<visual>
<origin xyz="0 0.00010468429334420381593 -0.028999999999999984124" rpy="1.570796326794896558 -1.1159600014435378954e-16 -1.5707963267948950037" />
<geometry>
<mesh filename="package:///spur_gear23.stl"/>
</geometry>
<material name="spur_gear23_material">
<color rgba="0.80000000000000004441 0.80000000000000004441 0.80000000000000004441 1.0"/>
</material>
</visual>
<collision>
<origin xyz="0 0.00010468429334420381593 -0.028999999999999984124" rpy="1.570796326794896558 -1.1159600014435378954e-16 -1.5707963267948950037" />
<geometry>
<mesh filename="package:///spur_gear23.stl"/>
</geometry>
</collision>
<visual>
<origin xyz="5.5511151231257827021e-17 0.0080000000000000071054 -0.0012500000000000011102" rpy="1.570796326794896558 -3.2551463119332395878e-19 3.7263109992003180383e-21" />
<geometry>
<mesh filename="package:///jgy-370output_shaft.stl"/>
</geometry>
<material name="jgy-370output_shaft_material">
<color rgba="0.79607843137254896693 0.79607843137254896693 0.79607843137254896693 1.0"/>
</material>
</visual>
<collision>
<origin xyz="5.5511151231257827021e-17 0.0080000000000000071054 -0.0012500000000000011102" rpy="1.570796326794896558 -3.2551463119332395878e-19 3.7263109992003180383e-21" />
<geometry>
<mesh filename="package:///jgy-370output_shaft.stl"/>
</geometry>
</collision>
<visual>
<origin xyz="1.1102230246251565404e-16 0.00010468429334431483824 -0.0070000000000000062172" rpy="-3.1415926535897900074 1.570796326794896336 0" />
<geometry>
<mesh filename="package:///part_1.stl"/>
</geometry>
<material name="part_1_material">
<color rgba="0.61568627450980395466 0.81176470588235294379 0.92941176470588238168 1.0"/>
</material>
</visual>
<collision>
<origin xyz="1.1102230246251565404e-16 0.00010468429334431483824 -0.0070000000000000062172" rpy="-3.1415926535897900074 1.570796326794896336 0" />
<geometry>
<mesh filename="package:///part_1.stl"/>
</geometry>
</collision>
<inertial>
<origin xyz="6.5693204755380554328e-06 0.00010403214169039786817 -0.029709602940672045351" rpy="0 0 0"/>
<mass value="0.043528139347743959042" />
<inertia ixx="1.9329540356905173745e-05" ixy="-1.8062857168699386502e-13"  ixz="-8.4588623058994275165e-10" iyy="1.9329599200350714875e-05" iyz="1.5151095876304807372e-09" izz="3.4179173231924735144e-05" />
</inertial>
</link>

<link name="lim_frame">
<visual>
<origin xyz="4.1633363423443370266e-16 4.4408920985006261617e-16 0.011499999999999385714" rpy="1.5707963267948850117 -4.7532741231252318989e-15 -4.0692067008561920691e-15" />
<geometry>
<mesh filename="package:///frame.stl"/>
</geometry>
<material name="frame_material">
<color rgba="0.80000000000000004441 0.80000000000000004441 0.80000000000000004441 1.0"/>
</material>
</visual>
<collision>
<origin xyz="4.1633363423443370266e-16 4.4408920985006261617e-16 0.011499999999999385714" rpy="1.5707963267948850117 -4.7532741231252318989e-15 -4.0692067008561920691e-15" />
<geometry>
<mesh filename="package:///frame.stl"/>
</geometry>
</collision>
<visual>
<origin xyz="0.041185522996315726552 0.028174738951837308143 0.014499999999999263478" rpy="1.5707963267948847896 -4.8069847065455337278e-15 -3.9521567125729650101e-15" />
<geometry>
<mesh filename="package:///m3_bolt_long.stl"/>
</geometry>
<material name="m3_bolt_long_material">
<color rgba="0.74901960784313725839 0.74901960784313725839 0.74901960784313725839 1.0"/>
</material>
</visual>
<collision>
<origin xyz="0.041185522996315726552 0.028174738951837308143 0.014499999999999263478" rpy="1.5707963267948847896 -4.8069847065455337278e-15 -3.9521567125729650101e-15" />
<geometry>
<mesh filename="package:///m3_bolt_long.stl"/>
</geometry>
</collision>
<visual>
<origin xyz="-0.13799999999999998379 0 -0.00049999999999993105515" rpy="-1.570796326794901665 3.3873154716883205177e-15 -1.6557557788532998364e-16" />
<geometry>
<mesh filename="package:///standoff1.stl"/>
</geometry>
<material name="standoff1_material">
<color rgba="0.80000000000000004441 0.80000000000000004441 0.80000000000000004441 1.0"/>
</material>
</visual>
<collision>
<origin xyz="-0.13799999999999998379 0 -0.00049999999999993105515" rpy="-1.570796326794901665 3.3873154716883205177e-15 -1.6557557788532998364e-16" />
<geometry>
<mesh filename="package:///standoff1.stl"/>
</geometry>
</collision>
<visual>
<origin xyz="-0.069999999999999368283 7.2164496600635175128e-16 0.0079999999999990217825" rpy="-1.5707963267948972241 -4.6738316598531235244e-16 -4.0405627712767499002e-15" />
<geometry>
<mesh filename="package:///m5-washer.stl"/>
</geometry>
<material name="m5-washer_material">
<color rgba="0.74509803921568629193 0.73725490196078435901 0.72941176470588231506 1.0"/>
</material>
</visual>
<collision>
<origin xyz="-0.069999999999999368283 7.2164496600635175128e-16 0.0079999999999990217825" rpy="-1.5707963267948972241 -4.6738316598531235244e-16 -4.0405627712767499002e-15" />
<geometry>
<mesh filename="package:///m5-washer.stl"/>
</geometry>
</collision>
<visual>
<origin xyz="-0.13800000000000001155 -5.5511151231257827021e-17 -0.0034999999999999614753" rpy="1.5707963267948974462 6.2594772733566218864e-16 1.5707963267948954478" />
<geometry>
<mesh filename="package:///m3-nut.stl"/>
</geometry>
<material name="m3-nut_material">
<color rgba="0.74509803921568629193 0.73725490196078435901 0.72941176470588231506 1.0"/>
</material>
</visual>
<collision>
<origin xyz="-0.13800000000000001155 -5.5511151231257827021e-17 -0.0034999999999999614753" rpy="1.5707963267948974462 6.2594772733566218864e-16 1.5707963267948954478" />
<geometry>
<mesh filename="package:///m3-nut.stl"/>
</geometry>
</collision>
<visual>
<origin xyz="-0.13799999999999912337 1.0547118733938987134e-15 0.014499999999998736122" rpy="1.5707963267948850117 -4.7670202222630848183e-15 -4.0571513292147684704e-15" />
<geometry>
<mesh filename="package:///m3_bolt_long.stl"/>
</geometry>
<material name="m3_bolt_long_material">
<color rgba="0.74901960784313725839 0.74901960784313725839 0.74901960784313725839 1.0"/>
</material>
</visual>
<collision>
<origin xyz="-0.13799999999999912337 1.0547118733938987134e-15 0.014499999999998736122" rpy="1.5707963267948850117 -4.7670202222630848183e-15 -4.0571513292147684704e-15" />
<geometry>
<mesh filename="package:///m3_bolt_long.stl"/>
</geometry>
</collision>
<visual>
<origin xyz="-0.070000000000000034417 -5.5511151231257827021e-17 2.7755575615628913511e-17" rpy="1.5707963267948961139 3.5938518273791762678e-16 -1.0478399059543940482e-16" />
<geometry>
<mesh filename="package:///m5-washer.stl"/>
</geometry>
<material name="m5-washer_material">
<color rgba="0.74509803921568629193 0.73725490196078435901 0.72941176470588231506 1.0"/>
</material>
</visual>
<collision>
<origin xyz="-0.070000000000000034417 -5.5511151231257827021e-17 2.7755575615628913511e-17" rpy="1.5707963267948961139 3.5938518273791762678e-16 -1.0478399059543940482e-16" />
<geometry>
<mesh filename="package:///m5-washer.stl"/>
</geometry>
</collision>
<visual>
<origin xyz="0.041185522996315337974 -0.028174738951836642009 -0.0035000000000000169864" rpy="1.5707963267948961139 3.4495110188310575601e-16 -1.0277476198853441168e-16" />
<geometry>
<mesh filename="package:///m3-nut.stl"/>
</geometry>
<material name="m3-nut_material">
<color rgba="0.74509803921568629193 0.73725490196078435901 0.72941176470588231506 1.0"/>
</material>
</visual>
<collision>
<origin xyz="0.041185522996315337974 -0.028174738951836642009 -0.0035000000000000169864" rpy="1.5707963267948961139 3.4495110188310575601e-16 -1.0277476198853441168e-16" />
<geometry>
<mesh filename="package:///m3-nut.stl"/>
</geometry>
</collision>
<visual>
<origin xyz="-0.041185522996315337974 0.028174738951836530987 -0.00050000000000001432188" rpy="-1.5707963267948972241 2.9163558447271609985e-16 -6.0580961243529148804e-17" />
<geometry>
<mesh filename="package:///standoff2.stl"/>
</geometry>
<material name="standoff2_material">
<color rgba="0.80000000000000004441 0.80000000000000004441 0.80000000000000004441 1.0"/>
</material>
</visual>
<collision>
<origin xyz="-0.041185522996315337974 0.028174738951836530987 -0.00050000000000001432188" rpy="-1.5707963267948972241 2.9163558447271609985e-16 -6.0580961243529148804e-17" />
<geometry>
<mesh filename="package:///standoff2.stl"/>
</geometry>
</collision>
<visual>
<origin xyz="-0.11100000000000001532 -5.5511151231257827021e-17 4.1633363423443370266e-17" rpy="1.5707963267948958919 -6.7695869302159867447e-16 -1.5707963267948976682" />
<geometry>
<mesh filename="package:///m5-washer.stl"/>
</geometry>
<material name="m5-washer_material">
<color rgba="0.74509803921568629193 0.73725490196078435901 0.72941176470588231506 1.0"/>
</material>
</visual>
<collision>
<origin xyz="-0.11100000000000001532 -5.5511151231257827021e-17 4.1633363423443370266e-17" rpy="1.5707963267948958919 -6.7695869302159867447e-16 -1.5707963267948976682" />
<geometry>
<mesh filename="package:///m5-washer.stl"/>
</geometry>
</collision>
<visual>
<origin xyz="-0.11099999999999922429 8.8817841970012523234e-16 0.0079999999999987997379" rpy="-1.5707963267948987784 1.1603491419487396683e-14 1.5707963267948934494" />
<geometry>
<mesh filename="package:///m5-washer.stl"/>
</geometry>
<material name="m5-washer_material">
<color rgba="0.74509803921568629193 0.73725490196078435901 0.72941176470588231506 1.0"/>
</material>
</visual>
<collision>
<origin xyz="-0.11099999999999922429 8.8817841970012523234e-16 0.0079999999999987997379" rpy="-1.5707963267948987784 1.1603491419487396683e-14 1.5707963267948934494" />
<geometry>
<mesh filename="package:///m5-washer.stl"/>
</geometry>
</collision>
<visual>
<origin xyz="-0.041185522996314727351 0.02817473895183764121 0.0144999999999988749" rpy="1.5707963267948850117 -4.6970749901770128032e-15 -4.1146717090529298361e-15" />
<geometry>
<mesh filename="package:///m3_bolt_long.stl"/>
</geometry>
<material name="m3_bolt_long_material">
<color rgba="0.74901960784313725839 0.74901960784313725839 0.74901960784313725839 1.0"/>
</material>
</visual>
<collision>
<origin xyz="-0.041185522996314727351 0.02817473895183764121 0.0144999999999988749" rpy="1.5707963267948850117 -4.6970749901770128032e-15 -4.1146717090529298361e-15" />
<geometry>
<mesh filename="package:///m3_bolt_long.stl"/>
</geometry>
</collision>
<visual>
<origin xyz="0.041185522996315393485 0.028174738951836530987 -0.003500000000000044742" rpy="1.5707963267948956698 3.169026105604173929e-16 -7.6654790098769291206e-17" />
<geometry>
<mesh filename="package:///m3-nut.stl"/>
</geometry>
<material name="m3-nut_material">
<color rgba="0.74509803921568629193 0.73725490196078435901 0.72941176470588231506 1.0"/>
</material>
</visual>
<collision>
<origin xyz="0.041185522996315393485 0.028174738951836530987 -0.003500000000000044742" rpy="1.5707963267948956698 3.169026105604173929e-16 -7.6654790098769291206e-17" />
<geometry>
<mesh filename="package:///m3-nut.stl"/>
</geometry>
</collision>
<visual>
<origin xyz="0.13800000000000001155 -5.5511151231257827021e-17 -0.0035000000000000586198" rpy="1.5707963267948932273 9.1917180190732720024e-16 -1.1609211247478708676e-16" />
<geometry>
<mesh filename="package:///m3-nut.stl"/>
</geometry>
<material name="m3-nut_material">
<color rgba="0.74509803921568629193 0.73725490196078435901 0.72941176470588231506 1.0"/>
</material>
</visual>
<collision>
<origin xyz="0.13800000000000001155 -5.5511151231257827021e-17 -0.0035000000000000586198" rpy="1.5707963267948932273 9.1917180190732720024e-16 -1.1609211247478708676e-16" />
<geometry>
<mesh filename="package:///m3-nut.stl"/>
</geometry>
</collision>
<visual>
<origin xyz="0.041185522996315337974 -0.028174738951836642009 -0.00050000000000001432188" rpy="-1.5707963267948972241 2.9801818532962586491e-16 -5.8571732636624131003e-17" />
<geometry>
<mesh filename="package:///standoff2.stl"/>
</geometry>
<material name="standoff2_material">
<color rgba="0.80000000000000004441 0.80000000000000004441 0.80000000000000004441 1.0"/>
</material>
</visual>
<collision>
<origin xyz="0.041185522996315337974 -0.028174738951836642009 -0.00050000000000001432188" rpy="-1.5707963267948972241 2.9801818532962586491e-16 -5.8571732636624131003e-17" />
<geometry>
<mesh filename="package:///standoff2.stl"/>
</geometry>
</collision>
<visual>
<origin xyz="0.041185522996315448996 0.028174738951836530987 -0.00050000000000002819966" rpy="-1.5707963267948972241 2.9163558447271609985e-16 -6.0580961243529148804e-17" />
<geometry>
<mesh filename="package:///standoff2.stl"/>
</geometry>
<material name="standoff2_material">
<color rgba="0.80000000000000004441 0.80000000000000004441 0.80000000000000004441 1.0"/>
</material>
</visual>
<collision>
<origin xyz="0.041185522996315448996 0.028174738951836530987 -0.00050000000000002819966" rpy="-1.5707963267948972241 2.9163558447271609985e-16 -6.0580961243529148804e-17" />
<geometry>
<mesh filename="package:///standoff2.stl"/>
</geometry>
</collision>
<visual>
<origin xyz="3.8857805861880478915e-16 4.4408920985006261617e-16 0.0079999999999993548494" rpy="-1.5707963267948961139 -1.4544211953771771347e-16 -4.1669116528324376192e-15" />
<geometry>
<mesh filename="package:///m5-washer.stl"/>
</geometry>
<material name="m5-washer_material">
<color rgba="0.74509803921568629193 0.73725490196078435901 0.72941176470588231506 1.0"/>
</material>
</visual>
<collision>
<origin xyz="3.8857805861880478915e-16 4.4408920985006261617e-16 0.0079999999999993548494" rpy="-1.5707963267948961139 -1.4544211953771771347e-16 -4.1669116528324376192e-15" />
<geometry>
<mesh filename="package:///m5-washer.stl"/>
</geometry>
</collision>
<visual>
<origin xyz="-0.041185522996314977151 -0.028174738951836364453 0.014499999999999541034" rpy="1.5707963267948850117 -4.7485604014093196513e-15 -4.0611697864285763366e-15" />
<geometry>
<mesh filename="package:///m3_bolt_long.stl"/>
</geometry>
<material name="m3_bolt_long_material">
<color rgba="0.74901960784313725839 0.74901960784313725839 0.74901960784313725839 1.0"/>
</material>
</visual>
<collision>
<origin xyz="-0.041185522996314977151 -0.028174738951836364453 0.014499999999999541034" rpy="1.5707963267948850117 -4.7485604014093196513e-15 -4.0611697864285763366e-15" />
<geometry>
<mesh filename="package:///m3_bolt_long.stl"/>
</geometry>
</collision>
<visual>
<origin xyz="-0.041185522996315448996 -0.02817473895183669752 0.0085000000000000908162" rpy="1.5707963267948972241 6.2764614484377709916e-16 1.5707963267948954478" />
<geometry>
<mesh filename="package:///standoff2.stl"/>
</geometry>
<material name="standoff2_material">
<color rgba="0.80000000000000004441 0.80000000000000004441 0.80000000000000004441 1.0"/>
</material>
</visual>
<collision>
<origin xyz="-0.041185522996315448996 -0.02817473895183669752 0.0085000000000000908162" rpy="1.5707963267948972241 6.2764614484377709916e-16 1.5707963267948954478" />
<geometry>
<mesh filename="package:///standoff2.stl"/>
</geometry>
</collision>
<visual>
<origin xyz="-5.5511151231257827021e-17 0 -0.0035000000000000169864" rpy="-1.5707963267948972241 3.3424984532018546384e-16 -7.665479009876927888e-17" />
<geometry>
<mesh filename="package:///frame.stl"/>
</geometry>
<material name="frame_material">
<color rgba="0.80000000000000004441 0.80000000000000004441 0.80000000000000004441 1.0"/>
</material>
</visual>
<collision>
<origin xyz="-5.5511151231257827021e-17 0 -0.0035000000000000169864" rpy="-1.5707963267948972241 3.3424984532018546384e-16 -7.665479009876927888e-17" />
<geometry>
<mesh filename="package:///frame.stl"/>
</geometry>
</collision>
<visual>
<origin xyz="0.13799999999999995604 -1.1102230246251565404e-16 0.014500000000000054512" rpy="1.5707963267948918951 1.1605439679133891822e-14 1.5707963267948934494" />
<geometry>
<mesh filename="package:///m3_bolt_long.stl"/>
</geometry>
<material name="m3_bolt_long_material">
<color rgba="0.74901960784313725839 0.74901960784313725839 0.74901960784313725839 1.0"/>
</material>
</visual>
<collision>
<origin xyz="0.13799999999999995604 -1.1102230246251565404e-16 0.014500000000000054512" rpy="1.5707963267948918951 1.1605439679133891822e-14 1.5707963267948934494" />
<geometry>
<mesh filename="package:///m3_bolt_long.stl"/>
</geometry>
</collision>
<visual>
<origin xyz="0.13799999999999995604 -5.5511151231257827021e-17 -0.00050000000000005595524" rpy="-1.570796326794896558 -5.6136789271461441491e-16 -1.5707963267948976682" />
<geometry>
<mesh filename="package:///standoff1.stl"/>
</geometry>
<material name="standoff1_material">
<color rgba="0.80000000000000004441 0.80000000000000004441 0.80000000000000004441 1.0"/>
</material>
</visual>
<collision>
<origin xyz="0.13799999999999995604 -5.5511151231257827021e-17 -0.00050000000000005595524" rpy="-1.570796326794896558 -5.6136789271461441491e-16 -1.5707963267948976682" />
<geometry>
<mesh filename="package:///standoff1.stl"/>
</geometry>
</collision>
<visual>
<origin xyz="0.041185522996315504507 -0.028174738951836753031 0.014499999999999901856" rpy="1.5707963267948847896 -4.6884672171321095364e-15 -4.065188243642383414e-15" />
<geometry>
<mesh filename="package:///m3_bolt_long.stl"/>
</geometry>
<material name="m3_bolt_long_material">
<color rgba="0.74901960784313725839 0.74901960784313725839 0.74901960784313725839 1.0"/>
</material>
</visual>
<collision>
<origin xyz="0.041185522996315504507 -0.028174738951836753031 0.014499999999999901856" rpy="1.5707963267948847896 -4.6884672171321095364e-15 -4.065188243642383414e-15" />
<geometry>
<mesh filename="package:///m3_bolt_long.stl"/>
</geometry>
</collision>
<visual>
<origin xyz="0.11099999999999993205 -5.5511151231257827021e-17 -2.7755575615628913511e-17" rpy="1.570796326794896336 -5.3220004769719130543e-16 -1.5707963267948976682" />
<geometry>
<mesh filename="package:///m5-washer.stl"/>
</geometry>
<material name="m5-washer_material">
<color rgba="0.74509803921568629193 0.73725490196078435901 0.72941176470588231506 1.0"/>
</material>
</visual>
<collision>
<origin xyz="0.11099999999999993205 -5.5511151231257827021e-17 -2.7755575615628913511e-17" rpy="1.570796326794896336 -5.3220004769719130543e-16 -1.5707963267948976682" />
<geometry>
<mesh filename="package:///m5-washer.stl"/>
</geometry>
</collision>
<visual>
<origin xyz="-0.041185522996315365729 0.028174738951836586498 -0.0035000000000000308642" rpy="1.5707963267948961139 3.9754909920940718564e-16 -1.6029514182669703463e-16" />
<geometry>
<mesh filename="package:///m3-nut.stl"/>
</geometry>
<material name="m3-nut_material">
<color rgba="0.74509803921568629193 0.73725490196078435901 0.72941176470588231506 1.0"/>
</material>
</visual>
<collision>
<origin xyz="-0.041185522996315365729 0.028174738951836586498 -0.0035000000000000308642" rpy="1.5707963267948961139 3.9754909920940718564e-16 -1.6029514182669703463e-16" />
<geometry>
<mesh filename="package:///m3-nut.stl"/>
</geometry>
</collision>
<visual>
<origin xyz="-0.041185522996315476751 -0.02817473895183669752 -0.003499999999999975353" rpy="1.5707963267948958919 3.7824006960158752167e-16 -1.2814748411621709495e-16" />
<geometry>
<mesh filename="package:///m3-nut.stl"/>
</geometry>
<material name="m3-nut_material">
<color rgba="0.74509803921568629193 0.73725490196078435901 0.72941176470588231506 1.0"/>
</material>
</visual>
<collision>
<origin xyz="-0.041185522996315476751 -0.02817473895183669752 -0.003499999999999975353" rpy="1.5707963267948958919 3.7824006960158752167e-16 -1.2814748411621709495e-16" />
<geometry>
<mesh filename="package:///m3-nut.stl"/>
</geometry>
</collision>
<visual>
<origin xyz="-2.7755575615628913511e-17 -5.5511151231257827021e-17 -1.3877787807814456755e-17" rpy="1.570796326794896558 -6.1762987832268911017e-19 2.8339826543031303272e-17" />
<geometry>
<mesh filename="package:///m5-washer.stl"/>
</geometry>
<material name="m5-washer_material">
<color rgba="0.74509803921568629193 0.73725490196078435901 0.72941176470588231506 1.0"/>
</material>
</visual>
<collision>
<origin xyz="-2.7755575615628913511e-17 -5.5511151231257827021e-17 -1.3877787807814456755e-17" rpy="1.570796326794896558 -6.1762987832268911017e-19 2.8339826543031303272e-17" />
<geometry>
<mesh filename="package:///m5-washer.stl"/>
</geometry>
</collision>
<visual>
<origin xyz="0.06999999999999995115 -5.5511151231257827021e-17 -2.7755575615628913511e-17" rpy="1.5707963267948970021 -3.3562580875411830558e-16 3.141592653589793116" />
<geometry>
<mesh filename="package:///m5-washer.stl"/>
</geometry>
<material name="m5-washer_material">
<color rgba="0.74509803921568629193 0.73725490196078435901 0.72941176470588231506 1.0"/>
</material>
</visual>
<collision>
<origin xyz="0.06999999999999995115 -5.5511151231257827021e-17 -2.7755575615628913511e-17" rpy="1.5707963267948970021 -3.3562580875411830558e-16 3.141592653589793116" />
<geometry>
<mesh filename="package:///m5-washer.stl"/>
</geometry>
</collision>
<visual>
<origin xyz="0.11100000000000004308 0 0.0079999999999999099609" rpy="-1.5707963267948981123 1.1605335060867011245e-14 1.5707963267948934494" />
<geometry>
<mesh filename="package:///m5-washer.stl"/>
</geometry>
<material name="m5-washer_material">
<color rgba="0.74509803921568629193 0.73725490196078435901 0.72941176470588231506 1.0"/>
</material>
</visual>
<collision>
<origin xyz="0.11100000000000004308 0 0.0079999999999999099609" rpy="-1.5707963267948981123 1.1605335060867011245e-14 1.5707963267948934494" />
<geometry>
<mesh filename="package:///m5-washer.stl"/>
</geometry>
</collision>
<visual>
<origin xyz="0.070000000000000228706 2.2204460492503130808e-16 0.0079999999999996879163" rpy="-1.5707963267948961139 4.7596567239821409737e-15 3.1415926535897891192" />
<geometry>
<mesh filename="package:///m5-washer.stl"/>
</geometry>
<material name="m5-washer_material">
<color rgba="0.74509803921568629193 0.73725490196078435901 0.72941176470588231506 1.0"/>
</material>
</visual>
<collision>
<origin xyz="0.070000000000000228706 2.2204460492503130808e-16 0.0079999999999996879163" rpy="-1.5707963267948961139 4.7596567239821409737e-15 3.1415926535897891192" />
<geometry>
<mesh filename="package:///m5-washer.stl"/>
</geometry>
</collision>
<inertial>
<origin xyz="1.7691636864265790831e-16 2.2298773586874279869e-16 0.0040706065685049480293" rpy="0 0 0"/>
<mass value="0.13451687861695468817" />
<inertia ixx="5.5430881089607574334e-05" ixy="1.3680026908725796057e-18"  ixz="-7.0792102055758235682e-19" iyy="0.00073807064970368241406" iyz="-3.9266254280162739174e-18" izz="0.00078364483939831626989" />
</inertial>
</link>

<link name="idler">
<visual>
<origin xyz="0 2.7755575615628913511e-17 0.0059999999999999914513" rpy="-1.5707963267948974462 1.5707963267948958919 0" />
<geometry>
<mesh filename="package:///shaft2.stl"/>
</geometry>
<material name="shaft2_material">
<color rgba="0.87843137254901959565 0.87450980392156862919 0.85882352941176465233 1.0"/>
</material>
</visual>
<collision>
<origin xyz="0 2.7755575615628913511e-17 0.0059999999999999914513" rpy="-1.5707963267948974462 1.5707963267948958919 0" />
<geometry>
<mesh filename="package:///shaft2.stl"/>
</geometry>
</collision>
<visual>
<origin xyz="0 0 0" rpy="1.570796326794896558 3.192578297170219966e-19 -4.4912825141998403867e-17" />
<geometry>
<mesh filename="package:///spur_gear13.stl"/>
</geometry>
<material name="spur_gear13_material">
<color rgba="0.80000000000000004441 0.80000000000000004441 0.80000000000000004441 1.0"/>
</material>
</visual>
<collision>
<origin xyz="0 0 0" rpy="1.570796326794896558 3.192578297170219966e-19 -4.4912825141998403867e-17" />
<geometry>
<mesh filename="package:///spur_gear13.stl"/>
</geometry>
</collision>
<inertial>
<origin xyz="5.2942742290570428455e-18 -8.6468797863596046039e-05 -0.0029999999999999996288" rpy="0 0 0"/>
<mass value="0.020048491397287253324" />
<inertia ixx="3.4759393485529689948e-06" ixy="-1.1872053270520226437e-22"  ixz="-2.8930326087290223983e-24" iyy="3.4784448550279069766e-06" iyz="-6.0732001370982144794e-23" izz="6.6798162389710824183e-06" />
</inertial>
</link>

<joint name="idler_c" type="revolute">
<origin xyz="0.070000000000000228706 2.2204460492503130808e-16 0.0079999999999996879163" rpy="-1.4164323340577334528e-15 3.7025772151567372099e-15 2.6685569241801592177" />
<parent link="lim_frame" />
<child link="idler" />
<axis xyz="0 0 1"/>
<limit effort="1" velocity="20" />
<joint_properties friction="0.0"/>
</joint>

<link name="idler_2">
<visual>
<origin xyz="-5.5511151231257827021e-17 2.7755575615628913511e-17 0" rpy="1.570796326794896558 -1.1634838279301026635e-18 -9.1235280451049641299e-17" />
<geometry>
<mesh filename="package:///spur_gear13.stl"/>
</geometry>
<material name="spur_gear13_material">
<color rgba="0.80000000000000004441 0.80000000000000004441 0.80000000000000004441 1.0"/>
</material>
</visual>
<collision>
<origin xyz="-5.5511151231257827021e-17 2.7755575615628913511e-17 0" rpy="1.570796326794896558 -1.1634838279301026635e-18 -9.1235280451049641299e-17" />
<geometry>
<mesh filename="package:///spur_gear13.stl"/>
</geometry>
</collision>
<visual>
<origin xyz="-5.5511151231257827021e-17 1.3877787807814456755e-17 0.0059999999999999636957" rpy="-1.57079632679489678 1.5707963267948956698 0" />
<geometry>
<mesh filename="package:///shaft2.stl"/>
</geometry>
<material name="shaft2_material">
<color rgba="0.87843137254901959565 0.87450980392156862919 0.85882352941176465233 1.0"/>
</material>
</visual>
<collision>
<origin xyz="-5.5511151231257827021e-17 1.3877787807814456755e-17 0.0059999999999999636957" rpy="-1.57079632679489678 1.5707963267948956698 0" />
<geometry>
<mesh filename="package:///shaft2.stl"/>
</geometry>
</collision>
<inertial>
<origin xyz="-5.0647065150142749071e-17 -8.6468797863574958307e-05 -0.0030000000000000043993" rpy="0 0 0"/>
<mass value="0.020048491397287253324" />
<inertia ixx="3.4759393485529702653e-06" ixy="-1.2825884851648693756e-22"  ixz="7.2889012948168135201e-23" iyy="3.4784448550279061295e-06" iyz="-1.1306851534916291022e-22" izz="6.6798162389710841124e-06" />
</inertial>
</link>

<joint name="idler_d" type="revolute">
<origin xyz="-0.06999999999999995115 1.1657341758564143674e-15 0.0079999999999999793499" rpy="7.1568118488118355445e-16 1.0327968037644009249e-16 2.2680270748056519103" />
<parent link="lim_frame" />
<child link="idler_2" />
<axis xyz="0 0 1"/>
<limit effort="1" velocity="20" />
<joint_properties friction="0.0"/>
</joint>

<link name="wheel_shaft">
<visual>
<origin xyz="-5.5511151231257827021e-17 4.1633363423443370266e-17 0.0049799999999999566835" rpy="1.570796326794896558 1.6631854135660137253e-15 0.13011746583638683639" />
<geometry>
<mesh filename="package:///m5-washer.stl"/>
</geometry>
<material name="m5-washer_material">
<color rgba="0.74509803921568629193 0.73725490196078435901 0.72941176470588231506 1.0"/>
</material>
</visual>
<collision>
<origin xyz="-5.5511151231257827021e-17 4.1633363423443370266e-17 0.0049799999999999566835" rpy="1.570796326794896558 1.6631854135660137253e-15 0.13011746583638683639" />
<geometry>
<mesh filename="package:///m5-washer.stl"/>
</geometry>
</collision>
<visual>
<origin xyz="-1.1102230246251565404e-16 4.1633363423443370266e-17 0.00498999999999999444" rpy="-1.5707963267948943376 -2.4913310400039443107e-15 -2.0943951023931832722" />
<geometry>
<mesh filename="package:///m5-nut-4mm.stl"/>
</geometry>
<material name="m5-nut-4mm_material">
<color rgba="0.74509803921568629193 0.73725490196078435901 0.72941176470588231506 1.0"/>
</material>
</visual>
<collision>
<origin xyz="-1.1102230246251565404e-16 4.1633363423443370266e-17 0.00498999999999999444" rpy="-1.5707963267948943376 -2.4913310400039443107e-15 -2.0943951023931832722" />
<geometry>
<mesh filename="package:///m5-nut-4mm.stl"/>
</geometry>
</collision>
<visual>
<origin xyz="-1.6653345369377348106e-16 1.1102230246251565404e-16 -0.012499999999999969469" rpy="1.5707963267948954478 -5.0557218521448077866e-16 -2.0943951023931832722" />
<geometry>
<mesh filename="package:///m5-nut-4mm.stl"/>
</geometry>
<material name="m5-nut-4mm_material">
<color rgba="0.74509803921568629193 0.73725490196078435901 0.72941176470588231506 1.0"/>
</material>
</visual>
<collision>
<origin xyz="-1.6653345369377348106e-16 1.1102230246251565404e-16 -0.012499999999999969469" rpy="1.5707963267948954478 -5.0557218521448077866e-16 -2.0943951023931832722" />
<geometry>
<mesh filename="package:///m5-nut-4mm.stl"/>
</geometry>
</collision>
<visual>
<origin xyz="-5.5511151231257827021e-17 -1.3877787807814456755e-17 0.020999999999999824363" rpy="1.5707963267948974462 2.8646171373857056171e-18 8.6820319554734690245e-16" />
<geometry>
<mesh filename="package:///m5-screw-cut.stl"/>
</geometry>
<material name="m5-screw-cut_material">
<color rgba="0.74901960784313725839 0.74901960784313725839 0.74901960784313725839 1.0"/>
</material>
</visual>
<collision>
<origin xyz="-5.5511151231257827021e-17 -1.3877787807814456755e-17 0.020999999999999824363" rpy="1.5707963267948974462 2.8646171373857056171e-18 8.6820319554734690245e-16" />
<geometry>
<mesh filename="package:///m5-screw-cut.stl"/>
</geometry>
</collision>
<visual>
<origin xyz="-2.553512956637860043e-15 4.1078251911130791996e-15 0.0159999999999998338" rpy="1.5707963267948938935 -9.5350400837053155723e-16 1.3010749678947339581e-14" />
<geometry>
<mesh filename="package:///nut-5.stl"/>
</geometry>
<material name="nut-5_material">
<color rgba="0.74509803921568629193 0.73725490196078435901 0.72941176470588231506 1.0"/>
</material>
</visual>
<collision>
<origin xyz="-2.553512956637860043e-15 4.1078251911130791996e-15 0.0159999999999998338" rpy="1.5707963267948938935 -9.5350400837053155723e-16 1.3010749678947339581e-14" />
<geometry>
<mesh filename="package:///nut-5.stl"/>
</geometry>
</collision>
<visual>
<origin xyz="-2.553512956637860043e-15 4.2466030691912237671e-15 0.0159999999999998338" rpy="1.5707963267948938935 -9.5350400837053155723e-16 1.3010749678947339581e-14" />
<geometry>
<mesh filename="package:///wheel.stl"/>
</geometry>
<material name="wheel_material">
<color rgba="0.21960784313725489891 0.18039215686274509554 0.12549019607843137081 1.0"/>
</material>
</visual>
<collision>
<origin xyz="-2.553512956637860043e-15 4.2466030691912237671e-15 0.0159999999999998338" rpy="1.5707963267948938935 -9.5350400837053155723e-16 1.3010749678947339581e-14" />
<geometry>
<mesh filename="package:///wheel.stl"/>
</geometry>
</collision>
<visual>
<origin xyz="0 0 0" rpy="1.570796326794896558 -1.4903445364945019031e-18 -3.6756730131458420783e-17" />
<geometry>
<mesh filename="package:///spur_gear22.stl"/>
</geometry>
<material name="spur_gear22_material">
<color rgba="0.80000000000000004441 0.80000000000000004441 0.80000000000000004441 1.0"/>
</material>
</visual>
<collision>
<origin xyz="0 0 0" rpy="1.570796326794896558 -1.4903445364945019031e-18 -3.6756730131458420783e-17" />
<geometry>
<mesh filename="package:///spur_gear22.stl"/>
</geometry>
</collision>
<visual>
<origin xyz="-5.5511151231257827021e-17 1.3877787807814456755e-17 -0.01150000000000003797" rpy="1.570796326794896558 1.4299284776792473647e-15 -0.02207975769648835504" />
<geometry>
<mesh filename="package:///m5-washer.stl"/>
</geometry>
<material name="m5-washer_material">
<color rgba="0.74509803921568629193 0.73725490196078435901 0.72941176470588231506 1.0"/>
</material>
</visual>
<collision>
<origin xyz="-5.5511151231257827021e-17 1.3877787807814456755e-17 -0.01150000000000003797" rpy="1.570796326794896558 1.4299284776792473647e-15 -0.02207975769648835504" />
<geometry>
<mesh filename="package:///m5-washer.stl"/>
</geometry>
</collision>
<inertial>
<origin xyz="-1.3338989029180838961e-15 3.1708361650537704934e-06 0.0063296302775223273196" rpy="0 0 0"/>
<mass value="0.077205002433972699794" />
<inertia ixx="6.6468537158775807777e-05" ixy="-1.0843469645718116671e-20"  ixz="6.1151829471508437791e-19" iyy="6.6468905141630905465e-05" iyz="7.4544680022298493767e-09" izz="0.0001201712566947735493" />
</inertial>
</link>

<joint name="wheel_c" type="revolute">
<origin xyz="0.11100000000000004308 0 0.0079999999999999099609" rpy="3.925487559252586102e-15 1.0310330126129698141e-14 2.1281244330296900102" />
<parent link="lim_frame" />
<child link="wheel_shaft" />
<axis xyz="0 0 1"/>
<limit effort="1" velocity="20" />
<joint_properties friction="0.0"/>
</joint>

<link name="wheel_shaft_2">
<visual>
<origin xyz="8.3266726846886740532e-17 2.2204460492503130808e-16 0.020999999999999921507" rpy="1.5707963267948974462 2.5471964466845852412e-19 1.0212940826158023455e-15" />
<geometry>
<mesh filename="package:///m5-screw-cut.stl"/>
</geometry>
<material name="m5-screw-cut_material">
<color rgba="0.74901960784313725839 0.74901960784313725839 0.74901960784313725839 1.0"/>
</material>
</visual>
<collision>
<origin xyz="8.3266726846886740532e-17 2.2204460492503130808e-16 0.020999999999999921507" rpy="1.5707963267948974462 2.5471964466845852412e-19 1.0212940826158023455e-15" />
<geometry>
<mesh filename="package:///m5-screw-cut.stl"/>
</geometry>
</collision>
<visual>
<origin xyz="5.5511151231257827021e-17 2.2204460492503130808e-16 0.0049800000000000121947" rpy="1.570796326794896558 1.6619560376247236567e-15 0.13011746583638722496" />
<geometry>
<mesh filename="package:///m5-washer.stl"/>
</geometry>
<material name="m5-washer_material">
<color rgba="0.74509803921568629193 0.73725490196078435901 0.72941176470588231506 1.0"/>
</material>
</visual>
<collision>
<origin xyz="5.5511151231257827021e-17 2.2204460492503130808e-16 0.0049800000000000121947" rpy="1.570796326794896558 1.6619560376247236567e-15 0.13011746583638722496" />
<geometry>
<mesh filename="package:///m5-washer.stl"/>
</geometry>
</collision>
<visual>
<origin xyz="-1.9428902930940239457e-16 0 0.0049899999999999111733" rpy="-1.5707963267948943376 -2.5206334963142267481e-15 -2.0943951023931828281" />
<geometry>
<mesh filename="package:///m5-nut-4mm.stl"/>
</geometry>
<material name="m5-nut-4mm_material">
<color rgba="0.74509803921568629193 0.73725490196078435901 0.72941176470588231506 1.0"/>
</material>
</visual>
<collision>
<origin xyz="-1.9428902930940239457e-16 0 0.0049899999999999111733" rpy="-1.5707963267948943376 -2.5206334963142267481e-15 -2.0943951023931828281" />
<geometry>
<mesh filename="package:///m5-nut-4mm.stl"/>
</geometry>
</collision>
<visual>
<origin xyz="-2.4424906541753443889e-15 4.1078251911130791996e-15 0.015999999999999861555" rpy="1.5707963267948938935 -9.6334324751017216194e-16 1.3348604213457855066e-14" />
<geometry>
<mesh filename="package:///nut-5.stl"/>
</geometry>
<material name="nut-5_material">
<color rgba="0.74509803921568629193 0.73725490196078435901 0.72941176470588231506 1.0"/>
</material>
</visual>
<collision>
<origin xyz="-2.4424906541753443889e-15 4.1078251911130791996e-15 0.015999999999999861555" rpy="1.5707963267948938935 -9.6334324751017216194e-16 1.3348604213457855066e-14" />
<geometry>
<mesh filename="package:///nut-5.stl"/>
</geometry>
</collision>
<visual>
<origin xyz="-2.7755575615628913511e-17 0 -0.011500000000000148992" rpy="1.570796326794896558 1.4245169775709316848e-15 -0.022079757696488521573" />
<geometry>
<mesh filename="package:///m5-washer.stl"/>
</geometry>
<material name="m5-washer_material">
<color rgba="0.74509803921568629193 0.73725490196078435901 0.72941176470588231506 1.0"/>
</material>
</visual>
<collision>
<origin xyz="-2.7755575615628913511e-17 0 -0.011500000000000148992" rpy="1.570796326794896558 1.4245169775709316848e-15 -0.022079757696488521573" />
<geometry>
<mesh filename="package:///m5-washer.stl"/>
</geometry>
</collision>
<visual>
<origin xyz="1.3877787807814456755e-16 0 -0.012499999999999983347" rpy="1.5707963267948954478 -5.3610983979676031954e-16 -2.0943951023931828281" />
<geometry>
<mesh filename="package:///m5-nut-4mm.stl"/>
</geometry>
<material name="m5-nut-4mm_material">
<color rgba="0.74509803921568629193 0.73725490196078435901 0.72941176470588231506 1.0"/>
</material>
</visual>
<collision>
<origin xyz="1.3877787807814456755e-16 0 -0.012499999999999983347" rpy="1.5707963267948954478 -5.3610983979676031954e-16 -2.0943951023931828281" />
<geometry>
<mesh filename="package:///m5-nut-4mm.stl"/>
</geometry>
</collision>
<visual>
<origin xyz="-2.7755575615628913511e-17 0 -1.3877787807814456755e-17" rpy="1.570796326794896558 3.8640831464080277697e-19 -7.7145367443405271894e-17" />
<geometry>
<mesh filename="package:///spur_gear22.stl"/>
</geometry>
<material name="spur_gear22_material">
<color rgba="0.80000000000000004441 0.80000000000000004441 0.80000000000000004441 1.0"/>
</material>
</visual>
<collision>
<origin xyz="-2.7755575615628913511e-17 0 -1.3877787807814456755e-17" rpy="1.570796326794896558 3.8640831464080277697e-19 -7.7145367443405271894e-17" />
<geometry>
<mesh filename="package:///spur_gear22.stl"/>
</geometry>
</collision>
<visual>
<origin xyz="-2.4702462297909733024e-15 4.1633363423443370266e-15 0.015999999999999861555" rpy="1.5707963267948938935 -9.6334324751017216194e-16 1.3348604213457855066e-14" />
<geometry>
<mesh filename="package:///wheel.stl"/>
</geometry>
<material name="wheel_material">
<color rgba="0.21960784313725489891 0.18039215686274509554 0.12549019607843137081 1.0"/>
</material>
</visual>
<collision>
<origin xyz="-2.4702462297909733024e-15 4.1633363423443370266e-15 0.015999999999999861555" rpy="1.5707963267948938935 -9.6334324751017216194e-16 1.3348604213457855066e-14" />
<geometry>
<mesh filename="package:///wheel.stl"/>
</geometry>
</collision>
<inertial>
<origin xyz="-1.2752875885190218243e-15 3.1708361650365291377e-06 0.0063296302775223446668" rpy="0 0 0"/>
<mass value="0.077205002433972699794" />
<inertia ixx="6.646853715877582133e-05" ixy="-5.1255412241379413138e-21"  ixz="5.970192327449278555e-19" iyy="6.6468905141630959675e-05" iyz="7.4544680022445103258e-09" izz="0.0001201712566947735764" />
</inertial>
</link>

<joint name="wheel_d" type="revolute">
<origin xyz="-0.11099999999999919653 8.8817841970012523234e-16 0.0079999999999987997379" rpy="-6.7482963394882867293e-15 9.8290467948461433558e-15 0.99854103579698927362" />
<parent link="lim_frame" />
<child link="wheel_shaft_2" />
<axis xyz="0 0 1"/>
<limit effort="1" velocity="20" />
<joint_properties friction="0.0"/>
</joint>

<joint name="sun_b" type="revolute">
<origin xyz="1.6653345369377348106e-16 0.00010468429334442586054 -0.02899999999999994249" rpy="-3.1415926535897917837 3.3251181200224165922e-16 1.3010147677694188229" />
<parent link="assembly_3" />
<child link="lim_frame" />
<axis xyz="0 0 1"/>
<limit effort="1" velocity="20" />
<joint_properties friction="0.0"/>
</joint>

<joint name="motor_b" type="revolute">
<origin xyz="-0.31783952686720584602 0.12803595497214695365 0.25552622161746796348" rpy="3.1325252042406694919 1.5607744624144965773 -1.5617285373929443715" />
<parent link="body" />
<child link="assembly_3" />
<axis xyz="0 0 1"/>
<limit effort="1" velocity="20" />
<joint_properties friction="0.0"/>
</joint>

<link name="assembly_3_2">
<visual>
<origin xyz="0 0.0079999999999999793499 -0.0012500000000000288658" rpy="1.570796326794896558 -2.0484868236051915659e-19 -5.0034935319226562835e-20" />
<geometry>
<mesh filename="package:///jgy-370output_shaft.stl"/>
</geometry>
<material name="jgy-370output_shaft_material">
<color rgba="0.79607843137254896693 0.79607843137254896693 0.79607843137254896693 1.0"/>
</material>
</visual>
<collision>
<origin xyz="0 0.0079999999999999793499 -0.0012500000000000288658" rpy="1.570796326794896558 -2.0484868236051915659e-19 -5.0034935319226562835e-20" />
<geometry>
<mesh filename="package:///jgy-370output_shaft.stl"/>
</geometry>
</collision>
<visual>
<origin xyz="5.5511151231257827021e-17 0.00010468429334425932709 -0.0070000000000000617284" rpy="3.1415926535897900074 1.570796326794896558 0" />
<geometry>
<mesh filename="package:///part_1.stl"/>
</geometry>
<material name="part_1_material">
<color rgba="0.61568627450980395466 0.81176470588235294379 0.92941176470588238168 1.0"/>
</material>
</visual>
<collision>
<origin xyz="5.5511151231257827021e-17 0.00010468429334425932709 -0.0070000000000000617284" rpy="3.1415926535897900074 1.570796326794896558 0" />
<geometry>
<mesh filename="package:///part_1.stl"/>
</geometry>
</collision>
<visual>
<origin xyz="-1.6653345369377348106e-16 0.00010468429334425932709 -0.028999999999999914735" rpy="1.570796326794896558 -1.2858444776767371738e-16 -1.57079632679489678" />
<geometry>
<mesh filename="package:///spur_gear23.stl"/>
</geometry>
<material name="spur_gear23_material">
<color rgba="0.80000000000000004441 0.80000000000000004441 0.80000000000000004441 1.0"/>
</material>
</visual>
<collision>
<origin xyz="-1.6653345369377348106e-16 0.00010468429334425932709 -0.028999999999999914735" rpy="1.570796326794896558 -1.2858444776767371738e-16 -1.57079632679489678" />
<geometry>
<mesh filename="package:///spur_gear23.stl"/>
</geometry>
</collision>
<inertial>
<origin xyz="6.5693204753842359436e-06 0.00010403214169044176481 -0.029709602940671969024" rpy="0 0 0"/>
<mass value="0.043528139347743959042" />
<inertia ixx="1.9329540356906274888e-05" ixy="-1.8062856466632340709e-13"  ixz="-8.4588623059890515019e-10" iyy="1.9329599200351209543e-05" iyz="1.5151095876432246953e-09" izz="3.4179173231924287911e-05" />
</inertial>
</link>

<link name="lim_frame_2">
<visual>
<origin xyz="-0.13799999999999412736 3.8857805861880478915e-16 0.014500000000000234923" rpy="1.5707963267948936714 -1.6607846255275266654e-16 -1.219139657725073049e-15" />
<geometry>
<mesh filename="package:///m3_bolt_long.stl"/>
</geometry>
<material name="m3_bolt_long_material">
<color rgba="0.74901960784313725839 0.74901960784313725839 0.74901960784313725839 1.0"/>
</material>
</visual>
<collision>
<origin xyz="-0.13799999999999412736 3.8857805861880478915e-16 0.014500000000000234923" rpy="1.5707963267948936714 -1.6607846255275266654e-16 -1.219139657725073049e-15" />
<geometry>
<mesh filename="package:///m3_bolt_long.stl"/>
</geometry>
</collision>
<visual>
<origin xyz="-0.04118552299631372815 -0.028174738951835642808 -0.003499999999999975353" rpy="1.5707963267948974462 -4.8766433618866135322e-18 3.6706435586685699492e-18" />
<geometry>
<mesh filename="package:///m3-nut.stl"/>
</geometry>
<material name="m3-nut_material">
<color rgba="0.74509803921568629193 0.73725490196078435901 0.72941176470588231506 1.0"/>
</material>
</visual>
<collision>
<origin xyz="-0.04118552299631372815 -0.028174738951835642808 -0.003499999999999975353" rpy="1.5707963267948974462 -4.8766433618866135322e-18 3.6706435586685699492e-18" />
<geometry>
<mesh filename="package:///m3-nut.stl"/>
</geometry>
</collision>
<visual>
<origin xyz="0.069999999999997120081 5.5511151231257827021e-17 5.5511151231257827021e-17" rpy="1.5707963267948956698 1.6069301061108745609e-16 3.141592653589793116" />
<geometry>
<mesh filename="package:///m5-washer.stl"/>
</geometry>
<material name="m5-washer_material">
<color rgba="0.74509803921568629193 0.73725490196078435901 0.72941176470588231506 1.0"/>
</material>
</visual>
<collision>
<origin xyz="0.069999999999997120081 5.5511151231257827021e-17 5.5511151231257827021e-17" rpy="1.5707963267948956698 1.6069301061108745609e-16 3.141592653589793116" />
<geometry>
<mesh filename="package:///m5-washer.stl"/>
</geometry>
</collision>
<visual>
<origin xyz="0.1109999999999954079 0 0.0080000000000000071054" rpy="-1.5707963267948956698 2.9036756123395238821e-15 1.5707963267949001107" />
<geometry>
<mesh filename="package:///m5-washer.stl"/>
</geometry>
<material name="m5-washer_material">
<color rgba="0.74509803921568629193 0.73725490196078435901 0.72941176470588231506 1.0"/>
</material>
</visual>
<collision>
<origin xyz="0.1109999999999954079 0 0.0080000000000000071054" rpy="-1.5707963267948956698 2.9036756123395238821e-15 1.5707963267949001107" />
<geometry>
<mesh filename="package:///m5-washer.stl"/>
</geometry>
</collision>
<visual>
<origin xyz="-0.069999999999997175593 0 8.3266726846886740532e-17" rpy="1.5707963267948976682 -4.7337584518745925665e-18 -1.0301315018071764517e-17" />
<geometry>
<mesh filename="package:///m5-washer.stl"/>
</geometry>
<material name="m5-washer_material">
<color rgba="0.74509803921568629193 0.73725490196078435901 0.72941176470588231506 1.0"/>
</material>
</visual>
<collision>
<origin xyz="-0.069999999999997175593 0 8.3266726846886740532e-17" rpy="1.5707963267948976682 -4.7337584518745925665e-18 -1.0301315018071764517e-17" />
<geometry>
<mesh filename="package:///m5-washer.stl"/>
</geometry>
</collision>
<visual>
<origin xyz="-0.11099999999999554667 0 0" rpy="1.570796326794896336 8.443670699287670309e-16 -1.5707963267948934494" />
<geometry>
<mesh filename="package:///m5-washer.stl"/>
</geometry>
<material name="m5-washer_material">
<color rgba="0.74509803921568629193 0.73725490196078435901 0.72941176470588231506 1.0"/>
</material>
</visual>
<collision>
<origin xyz="-0.11099999999999554667 0 0" rpy="1.570796326794896336 8.443670699287670309e-16 -1.5707963267948934494" />
<geometry>
<mesh filename="package:///m5-washer.stl"/>
</geometry>
</collision>
<visual>
<origin xyz="0.041185522996313561617 0.028174738951835587297 -0.0034999999999999475975" rpy="1.5707963267948972241 -1.3369186252293233158e-18 -3.2814544118114271961e-18" />
<geometry>
<mesh filename="package:///m3-nut.stl"/>
</geometry>
<material name="m3-nut_material">
<color rgba="0.74509803921568629193 0.73725490196078435901 0.72941176470588231506 1.0"/>
</material>
</visual>
<collision>
<origin xyz="0.041185522996313561617 0.028174738951835587297 -0.0034999999999999475975" rpy="1.5707963267948972241 -1.3369186252293233158e-18 -3.2814544118114271961e-18" />
<geometry>
<mesh filename="package:///m3-nut.stl"/>
</geometry>
</collision>
<visual>
<origin xyz="-0.04118552299631372815 0.02817473895183594812 0.014499999999999985123" rpy="1.5707963267948936714 -1.6607846255275266654e-16 -1.219139657725073049e-15" />
<geometry>
<mesh filename="package:///m3_bolt_long.stl"/>
</geometry>
<material name="m3_bolt_long_material">
<color rgba="0.74901960784313725839 0.74901960784313725839 0.74901960784313725839 1.0"/>
</material>
</visual>
<collision>
<origin xyz="-0.04118552299631372815 0.02817473895183594812 0.014499999999999985123" rpy="1.5707963267948936714 -1.6607846255275266654e-16 -1.219139657725073049e-15" />
<geometry>
<mesh filename="package:///m3_bolt_long.stl"/>
</geometry>
</collision>
<visual>
<origin xyz="-0.041185522996313506106 -0.028174738951835476275 0.014500000000000207168" rpy="1.5707963267948936714 -1.6607846255275266654e-16 -1.219139657725073049e-15" />
<geometry>
<mesh filename="package:///m3_bolt_long.stl"/>
</geometry>
<material name="m3_bolt_long_material">
<color rgba="0.74901960784313725839 0.74901960784313725839 0.74901960784313725839 1.0"/>
</material>
</visual>
<collision>
<origin xyz="-0.041185522996313506106 -0.028174738951835476275 0.014500000000000207168" rpy="1.5707963267948936714 -1.6607846255275266654e-16 -1.219139657725073049e-15" />
<geometry>
<mesh filename="package:///m3_bolt_long.stl"/>
</geometry>
</collision>
<visual>
<origin xyz="-1.1102230246251565404e-16 0 -0.0034999999999999198419" rpy="-1.5707963267948956698 -1.3384009328870189192e-18 -3.2543493574992899704e-18" />
<geometry>
<mesh filename="package:///frame.stl"/>
</geometry>
<material name="frame_material">
<color rgba="0.80000000000000004441 0.80000000000000004441 0.80000000000000004441 1.0"/>
</material>
</visual>
<collision>
<origin xyz="-1.1102230246251565404e-16 0 -0.0034999999999999198419" rpy="-1.5707963267948956698 -1.3384009328870189192e-18 -3.2543493574992899704e-18" />
<geometry>
<mesh filename="package:///frame.stl"/>
</geometry>
</collision>
<visual>
<origin xyz="0.041185522996313617128 0.028174738951835837097 0.014499999999999985123" rpy="1.5707963267948936714 -1.6607846255275266654e-16 -1.219139657725073049e-15" />
<geometry>
<mesh filename="package:///m3_bolt_long.stl"/>
</geometry>
<material name="m3_bolt_long_material">
<color rgba="0.74901960784313725839 0.74901960784313725839 0.74901960784313725839 1.0"/>
</material>
</visual>
<collision>
<origin xyz="0.041185522996313617128 0.028174738951835837097 0.014499999999999985123" rpy="1.5707963267948936714 -1.6607846255275266654e-16 -1.219139657725073049e-15" />
<geometry>
<mesh filename="package:///m3_bolt_long.stl"/>
</geometry>
</collision>
<visual>
<origin xyz="-0.06999999999999706457 2.7755575615628913511e-16 0.0080000000000000903722" rpy="-1.5707963267948956698 -1.6252762050866210665e-16 -1.2263357011843584004e-15" />
<geometry>
<mesh filename="package:///m5-washer.stl"/>
</geometry>
<material name="m5-washer_material">
<color rgba="0.74509803921568629193 0.73725490196078435901 0.72941176470588231506 1.0"/>
</material>
</visual>
<collision>
<origin xyz="-0.06999999999999706457 2.7755575615628913511e-16 0.0080000000000000903722" rpy="-1.5707963267948956698 -1.6252762050866210665e-16 -1.2263357011843584004e-15" />
<geometry>
<mesh filename="package:///m5-washer.stl"/>
</geometry>
</collision>
<visual>
<origin xyz="-0.041185522996313783661 -0.028174738951835642808 0.0085000000000000630607" rpy="1.570796326794896558 -8.6931164194228857245e-16 1.5707963267948998887" />
<geometry>
<mesh filename="package:///standoff2.stl"/>
</geometry>
<material name="standoff2_material">
<color rgba="0.80000000000000004441 0.80000000000000004441 0.80000000000000004441 1.0"/>
</material>
</visual>
<collision>
<origin xyz="-0.041185522996313783661 -0.028174738951835642808 0.0085000000000000630607" rpy="1.570796326794896558 -8.6931164194228857245e-16 1.5707963267948998887" />
<geometry>
<mesh filename="package:///standoff2.stl"/>
</geometry>
</collision>
<visual>
<origin xyz="0.041185522996313783661 -0.028174738951835642808 0.014500000000000179412" rpy="1.5707963267948936714 -1.5913956864884509303e-16 -1.2191125526707605169e-15" />
<geometry>
<mesh filename="package:///m3_bolt_long.stl"/>
</geometry>
<material name="m3_bolt_long_material">
<color rgba="0.74901960784313725839 0.74901960784313725839 0.74901960784313725839 1.0"/>
</material>
</visual>
<collision>
<origin xyz="0.041185522996313783661 -0.028174738951835642808 0.014500000000000179412" rpy="1.5707963267948936714 -1.5913956864884509303e-16 -1.2191125526707605169e-15" />
<geometry>
<mesh filename="package:///m3_bolt_long.stl"/>
</geometry>
</collision>
<visual>
<origin xyz="0.041185522996313561617 0.028174738951835642808 -0.00049999999999991717736" rpy="-1.5707963267948958919 -4.8093301924984739265e-18 -3.22724430318715313e-18" />
<geometry>
<mesh filename="package:///standoff2.stl"/>
</geometry>
<material name="standoff2_material">
<color rgba="0.80000000000000004441 0.80000000000000004441 0.80000000000000004441 1.0"/>
</material>
</visual>
<collision>
<origin xyz="0.041185522996313561617 0.028174738951835642808 -0.00049999999999991717736" rpy="-1.5707963267948958919 -4.8093301924984739265e-18 -3.22724430318715313e-18" />
<geometry>
<mesh filename="package:///standoff2.stl"/>
</geometry>
</collision>
<visual>
<origin xyz="-0.041185522996313839172 0.028174738951835615053 -0.00049999999999983391064" rpy="-1.5707963267948958919 -4.8093301924984739265e-18 -3.22724430318715313e-18" />
<geometry>
<mesh filename="package:///standoff2.stl"/>
</geometry>
<material name="standoff2_material">
<color rgba="0.80000000000000004441 0.80000000000000004441 0.80000000000000004441 1.0"/>
</material>
</visual>
<collision>
<origin xyz="-0.041185522996313839172 0.028174738951835615053 -0.00049999999999983391064" rpy="-1.5707963267948958919 -4.8093301924984739265e-18 -3.22724430318715313e-18" />
<geometry>
<mesh filename="package:///standoff2.stl"/>
</geometry>
</collision>
<visual>
<origin xyz="0.04118552299631372815 -0.02817473895183569832 -0.003499999999999975353" rpy="1.5707963267948974462 -8.2024642499994979095e-18 -1.0341972599539972474e-17" />
<geometry>
<mesh filename="package:///m3-nut.stl"/>
</geometry>
<material name="m3-nut_material">
<color rgba="0.74509803921568629193 0.73725490196078435901 0.72941176470588231506 1.0"/>
</material>
</visual>
<collision>
<origin xyz="0.04118552299631372815 -0.02817473895183569832 -0.003499999999999975353" rpy="1.5707963267948974462 -8.2024642499994979095e-18 -1.0341972599539972474e-17" />
<geometry>
<mesh filename="package:///m3-nut.stl"/>
</geometry>
</collision>
<visual>
<origin xyz="0.069999999999997036815 0 0.00800000000000022915" rpy="-1.5707963267948970021 -2.3836980220760831313e-15 3.1415926535897922278" />
<geometry>
<mesh filename="package:///m5-washer.stl"/>
</geometry>
<material name="m5-washer_material">
<color rgba="0.74509803921568629193 0.73725490196078435901 0.72941176470588231506 1.0"/>
</material>
</visual>
<collision>
<origin xyz="0.069999999999997036815 0 0.00800000000000022915" rpy="-1.5707963267948970021 -2.3836980220760831313e-15 3.1415926535897922278" />
<geometry>
<mesh filename="package:///m5-washer.stl"/>
</geometry>
</collision>
<visual>
<origin xyz="5.5511151231257827021e-17 0 0" rpy="1.570796326794896558 2.2209633405125888978e-18 -2.9196354938364154434e-20" />
<geometry>
<mesh filename="package:///m5-washer.stl"/>
</geometry>
<material name="m5-washer_material">
<color rgba="0.74509803921568629193 0.73725490196078435901 0.72941176470588231506 1.0"/>
</material>
</visual>
<collision>
<origin xyz="5.5511151231257827021e-17 0 0" rpy="1.570796326794896558 2.2209633405125888978e-18 -2.9196354938364154434e-20" />
<geometry>
<mesh filename="package:///m5-washer.stl"/>
</geometry>
</collision>
<visual>
<origin xyz="0 1.6653345369377348106e-16 0.011500000000000121236" rpy="1.5707963267948936714 -1.6253873781609528773e-16 -1.2260782031683964458e-15" />
<geometry>
<mesh filename="package:///frame.stl"/>
</geometry>
<material name="frame_material">
<color rgba="0.80000000000000004441 0.80000000000000004441 0.80000000000000004441 1.0"/>
</material>
</visual>
<collision>
<origin xyz="0 1.6653345369377348106e-16 0.011500000000000121236" rpy="1.5707963267948936714 -1.6253873781609528773e-16 -1.2260782031683964458e-15" />
<geometry>
<mesh filename="package:///frame.stl"/>
</geometry>
</collision>
<visual>
<origin xyz="0.1379999999999942939 5.5511151231257827021e-17 -0.0035000000000000586198" rpy="1.5707963267948961139 -1.1993276711376469272e-18 -1.7131440244147150117e-17" />
<geometry>
<mesh filename="package:///m3-nut.stl"/>
</geometry>
<material name="m3-nut_material">
<color rgba="0.74509803921568629193 0.73725490196078435901 0.72941176470588231506 1.0"/>
</material>
</visual>
<collision>
<origin xyz="0.1379999999999942939 5.5511151231257827021e-17 -0.0035000000000000586198" rpy="1.5707963267948961139 -1.1993276711376469272e-18 -1.7131440244147150117e-17" />
<geometry>
<mesh filename="package:///m3-nut.stl"/>
</geometry>
</collision>
<visual>
<origin xyz="-0.13799999999999440492 0 -0.00050000000000000044409" rpy="-1.5707963267948972241 -4.7412758692814837265e-18 -1.0125132165042882372e-17" />
<geometry>
<mesh filename="package:///standoff1.stl"/>
</geometry>
<material name="standoff1_material">
<color rgba="0.80000000000000004441 0.80000000000000004441 0.80000000000000004441 1.0"/>
</material>
</visual>
<collision>
<origin xyz="-0.13799999999999440492 0 -0.00050000000000000044409" rpy="-1.5707963267948972241 -4.7412758692814837265e-18 -1.0125132165042882372e-17" />
<geometry>
<mesh filename="package:///standoff1.stl"/>
</geometry>
</collision>
<visual>
<origin xyz="0 1.1102230246251565404e-16 0.0080000000000001458833" rpy="-1.570796326794896558 -1.6259112202978734383e-16 -1.2195326810125931279e-15" />
<geometry>
<mesh filename="package:///m5-washer.stl"/>
</geometry>
<material name="m5-washer_material">
<color rgba="0.74509803921568629193 0.73725490196078435901 0.72941176470588231506 1.0"/>
</material>
</visual>
<collision>
<origin xyz="0 1.1102230246251565404e-16 0.0080000000000001458833" rpy="-1.570796326794896558 -1.6259112202978734383e-16 -1.2195326810125931279e-15" />
<geometry>
<mesh filename="package:///m5-washer.stl"/>
</geometry>
</collision>
<visual>
<origin xyz="-0.13799999999999446043 0 -0.0034999999999999198419" rpy="1.57079632679489678 -9.9336252345856596116e-16 1.5707963267948998887" />
<geometry>
<mesh filename="package:///m3-nut.stl"/>
</geometry>
<material name="m3-nut_material">
<color rgba="0.74509803921568629193 0.73725490196078435901 0.72941176470588231506 1.0"/>
</material>
</visual>
<collision>
<origin xyz="-0.13799999999999446043 0 -0.0034999999999999198419" rpy="1.57079632679489678 -9.9336252345856596116e-16 1.5707963267948998887" />
<geometry>
<mesh filename="package:///m3-nut.stl"/>
</geometry>
</collision>
<visual>
<origin xyz="-0.041185522996313894684 0.028174738951835615053 -0.0035000000000000031086" rpy="1.5707963267948974462 -4.7322761442168960002e-18 -1.0341972599539969392e-17" />
<geometry>
<mesh filename="package:///m3-nut.stl"/>
</geometry>
<material name="m3-nut_material">
<color rgba="0.74509803921568629193 0.73725490196078435901 0.72941176470588231506 1.0"/>
</material>
</visual>
<collision>
<origin xyz="-0.041185522996313894684 0.028174738951835615053 -0.0035000000000000031086" rpy="1.5707963267948974462 -4.7322761442168960002e-18 -1.0341972599539969392e-17" />
<geometry>
<mesh filename="package:///m3-nut.stl"/>
</geometry>
</collision>
<visual>
<origin xyz="-0.11099999999999532463 2.7755575615628913511e-16 0.0079999999999999793499" rpy="-1.5707963267948958919 2.904370361657220681e-15 1.5707963267949001107" />
<geometry>
<mesh filename="package:///m5-washer.stl"/>
</geometry>
<material name="m5-washer_material">
<color rgba="0.74509803921568629193 0.73725490196078435901 0.72941176470588231506 1.0"/>
</material>
</visual>
<collision>
<origin xyz="-0.11099999999999532463 2.7755575615628913511e-16 0.0079999999999999793499" rpy="-1.5707963267948958919 2.904370361657220681e-15 1.5707963267949001107" />
<geometry>
<mesh filename="package:///m5-washer.stl"/>
</geometry>
</collision>
<visual>
<origin xyz="0.13799999999999426614 0 0.01450000000000006839" rpy="1.5707963267948958919 3.6048761918776808564e-15 1.5707963267949001107" />
<geometry>
<mesh filename="package:///m3_bolt_long.stl"/>
</geometry>
<material name="m3_bolt_long_material">
<color rgba="0.74901960784313725839 0.74901960784313725839 0.74901960784313725839 1.0"/>
</material>
</visual>
<collision>
<origin xyz="0.13799999999999426614 0 0.01450000000000006839" rpy="1.5707963267948958919 3.6048761918776808564e-15 1.5707963267949001107" />
<geometry>
<mesh filename="package:///m3_bolt_long.stl"/>
</geometry>
</collision>
<visual>
<origin xyz="0.11099999999999535238 -1.1102230246251565404e-16 8.3266726846886740532e-17" rpy="1.570796326794896558 8.4315910113266654706e-16 -1.5707963267948934494" />
<geometry>
<mesh filename="package:///m5-washer.stl"/>
</geometry>
<material name="m5-washer_material">
<color rgba="0.74509803921568629193 0.73725490196078435901 0.72941176470588231506 1.0"/>
</material>
</visual>
<collision>
<origin xyz="0.11099999999999535238 -1.1102230246251565404e-16 8.3266726846886740532e-17" rpy="1.570796326794896558 8.4315910113266654706e-16 -1.5707963267948934494" />
<geometry>
<mesh filename="package:///m5-washer.stl"/>
</geometry>
</collision>
<visual>
<origin xyz="0.041185522996313783661 -0.02817473895183569832 -0.00050000000000005595524" rpy="-1.5707963267948958919 -4.8093301924984739265e-18 -3.22724430318715313e-18" />
<geometry>
<mesh filename="package:///standoff2.stl"/>
</geometry>
<material name="standoff2_material">
<color rgba="0.80000000000000004441 0.80000000000000004441 0.80000000000000004441 1.0"/>
</material>
</visual>
<collision>
<origin xyz="0.041185522996313783661 -0.02817473895183569832 -0.00050000000000005595524" rpy="-1.5707963267948958919 -4.8093301924984739265e-18 -3.22724430318715313e-18" />
<geometry>
<mesh filename="package:///standoff2.stl"/>
</geometry>
</collision>
<visual>
<origin xyz="0.13799999999999426614 -5.5511151231257827021e-17 -0.00049999999999994493294" rpy="-1.570796326794896558 8.4266865242065369811e-16 -1.5707963267948934494" />
<geometry>
<mesh filename="package:///standoff1.stl"/>
</geometry>
<material name="standoff1_material">
<color rgba="0.80000000000000004441 0.80000000000000004441 0.80000000000000004441 1.0"/>
</material>
</visual>
<collision>
<origin xyz="0.13799999999999426614 -5.5511151231257827021e-17 -0.00049999999999994493294" rpy="-1.570796326794896558 8.4266865242065369811e-16 -1.5707963267948934494" />
<geometry>
<mesh filename="package:///standoff1.stl"/>
</geometry>
</collision>
<inertial>
<origin xyz="-5.8434791465114783516e-17 8.2606022999589557099e-17 0.0040706065685053634956" rpy="0 0 0"/>
<mass value="0.13451687861695471593" />
<inertia ixx="5.5430881089603969362e-05" ixy="-1.5681956371156528829e-18"  ixz="5.7521147180202480877e-19" iyy="0.00073807064970362505976" iyz="-5.4365837326357448061e-19" izz="0.00078364483939829295955" />
</inertial>
</link>

<link name="idler_3">
<visual>
<origin xyz="2.3418766925686895775e-17 0 0" rpy="1.570796326794896558 -3.1135379234656890829e-18 2.7296175703936780396e-17" />
<geometry>
<mesh filename="package:///spur_gear13.stl"/>
</geometry>
<material name="spur_gear13_material">
<color rgba="0.80000000000000004441 0.80000000000000004441 0.80000000000000004441 1.0"/>
</material>
</visual>
<collision>
<origin xyz="2.3418766925686895775e-17 0 0" rpy="1.570796326794896558 -3.1135379234656890829e-18 2.7296175703936780396e-17" />
<geometry>
<mesh filename="package:///spur_gear13.stl"/>
</geometry>
</collision>
<visual>
<origin xyz="-8.6736173798840354721e-18 5.5511151231257827021e-17 0.0059999999999999775735" rpy="-1.57079632679489678 1.570796326794896336 0" />
<geometry>
<mesh filename="package:///shaft2.stl"/>
</geometry>
<material name="shaft2_material">
<color rgba="0.87843137254901959565 0.87450980392156862919 0.85882352941176465233 1.0"/>
</material>
</visual>
<collision>
<origin xyz="-8.6736173798840354721e-18 5.5511151231257827021e-17 0.0059999999999999775735" rpy="-1.57079632679489678 1.570796326794896336 0" />
<geometry>
<mesh filename="package:///shaft2.stl"/>
</geometry>
</collision>
<inertial>
<origin xyz="2.391193830514494415e-17 -8.6468797863592115806e-05 -0.0030000000000000039656" rpy="0 0 0"/>
<mass value="0.020048491397287253324" />
<inertia ixx="3.4759393485529694183e-06" ixy="4.3694433013489163287e-22"  ixz="2.8979354995640912342e-23" iyy="3.478444855027906553e-06" iyz="-4.5425447263476592834e-23" izz="6.6798162389710841124e-06" />
</inertial>
</link>

<joint name="idler_a" type="revolute">
<origin xyz="0.069999999999997036815 0 0.00800000000000022915" rpy="2.05761454752299006e-15 -1.7554786218493166925e-15 2.3580333328824618633" />
<parent link="lim_frame_2" />
<child link="idler_3" />
<axis xyz="0 0 1"/>
<limit effort="1" velocity="20" />
<joint_properties friction="0.0"/>
</joint>

<link name="idler_4">
<visual>
<origin xyz="0 3.8163916471489756077e-17 -2.7755575615628913511e-17" rpy="1.570796326794896558 -7.3724811433567177976e-19 3.3177751908257896765e-17" />
<geometry>
<mesh filename="package:///spur_gear13.stl"/>
</geometry>
<material name="spur_gear13_material">
<color rgba="0.80000000000000004441 0.80000000000000004441 0.80000000000000004441 1.0"/>
</material>
</visual>
<collision>
<origin xyz="0 3.8163916471489756077e-17 -2.7755575615628913511e-17" rpy="1.570796326794896558 -7.3724811433567177976e-19 3.3177751908257896765e-17" />
<geometry>
<mesh filename="package:///spur_gear13.stl"/>
</geometry>
</collision>
<visual>
<origin xyz="0 2.7755575615628913511e-17 0.0059999999999999775735" rpy="-1.57079632679489678 1.5707963267948961139 0" />
<geometry>
<mesh filename="package:///shaft2.stl"/>
</geometry>
<material name="shaft2_material">
<color rgba="0.87843137254901959565 0.87450980392156862919 0.85882352941176465233 1.0"/>
</material>
</visual>
<collision>
<origin xyz="0 2.7755575615628913511e-17 0.0059999999999999775735" rpy="-1.57079632679489678 1.5707963267948961139 0" />
<geometry>
<mesh filename="package:///shaft2.stl"/>
</geometry>
</collision>
<inertial>
<origin xyz="5.396665168239747506e-18 -8.6468797863564522861e-05 -0.0030000000000000286854" rpy="0 0 0"/>
<mass value="0.020048491397287253324" />
<inertia ixx="3.4759393485529694183e-06" ixy="-2.7543079941707262843e-22"  ixz="2.557028874821056866e-23" iyy="3.4784448550279061295e-06" iyz="-5.1933864829099302556e-24" izz="6.6798162389710875005e-06" />
</inertial>
</link>

<joint name="idler_b" type="revolute">
<origin xyz="-0.06999999999999706457 2.7755575615628913511e-16 0.0080000000000000903722" rpy="2.8375496426252807701e-16 2.075297764247214519e-15 -2.5897213190487309298" />
<parent link="lim_frame_2" />
<child link="idler_4" />
<axis xyz="0 0 1"/>
<limit effort="1" velocity="20" />
<joint_properties friction="0.0"/>
</joint>

<link name="wheel_shaft_3">
<visual>
<origin xyz="-2.3869795029440865619e-15 3.8302694349567900645e-15 0.016000000000000097478" rpy="1.5707963267948938935 -9.2223177152591383994e-16 1.27915869518218299e-14" />
<geometry>
<mesh filename="package:///nut-5.stl"/>
</geometry>
<material name="nut-5_material">
<color rgba="0.74509803921568629193 0.73725490196078435901 0.72941176470588231506 1.0"/>
</material>
</visual>
<collision>
<origin xyz="-2.3869795029440865619e-15 3.8302694349567900645e-15 0.016000000000000097478" rpy="1.5707963267948938935 -9.2223177152591383994e-16 1.27915869518218299e-14" />
<geometry>
<mesh filename="package:///nut-5.stl"/>
</geometry>
</collision>
<visual>
<origin xyz="-2.1094237467877974268e-15 4.1910919179599659401e-15 0.0160000000000002085" rpy="1.5707963267948938935 -9.2223177152591383994e-16 1.27915869518218299e-14" />
<geometry>
<mesh filename="package:///wheel.stl"/>
</geometry>
<material name="wheel_material">
<color rgba="0.21960784313725489891 0.18039215686274509554 0.12549019607843137081 1.0"/>
</material>
</visual>
<collision>
<origin xyz="-2.1094237467877974268e-15 4.1910919179599659401e-15 0.0160000000000002085" rpy="1.5707963267948938935 -9.2223177152591383994e-16 1.27915869518218299e-14" />
<geometry>
<mesh filename="package:///wheel.stl"/>
</geometry>
</collision>
<visual>
<origin xyz="-5.5511151231257827021e-17 2.498001805406602216e-16 -0.011499999999999482858" rpy="1.570796326794896558 1.4448657892628101905e-15 -0.022079757696487404411" />
<geometry>
<mesh filename="package:///m5-washer.stl"/>
</geometry>
<material name="m5-washer_material">
<color rgba="0.74509803921568629193 0.73725490196078435901 0.72941176470588231506 1.0"/>
</material>
</visual>
<collision>
<origin xyz="-5.5511151231257827021e-17 2.498001805406602216e-16 -0.011499999999999482858" rpy="1.570796326794896558 1.4448657892628101905e-15 -0.022079757696487404411" />
<geometry>
<mesh filename="package:///m5-washer.stl"/>
</geometry>
</collision>
<visual>
<origin xyz="0 -2.7755575615628913511e-17 0" rpy="1.570796326794896558 1.4038611647081121614e-18 -1.3621416010421857582e-17" />
<geometry>
<mesh filename="package:///spur_gear22.stl"/>
</geometry>
<material name="spur_gear22_material">
<color rgba="0.80000000000000004441 0.80000000000000004441 0.80000000000000004441 1.0"/>
</material>
</visual>
<collision>
<origin xyz="0 -2.7755575615628913511e-17 0" rpy="1.570796326794896558 1.4038611647081121614e-18 -1.3621416010421857582e-17" />
<geometry>
<mesh filename="package:///spur_gear22.stl"/>
</geometry>
</collision>
<visual>
<origin xyz="2.2204460492503130808e-16 -2.498001805406602216e-16 -0.012499999999999927836" rpy="1.5707963267948954478 -5.6398111784001782669e-16 -2.0943951023931832722" />
<geometry>
<mesh filename="package:///m5-nut-4mm.stl"/>
</geometry>
<material name="m5-nut-4mm_material">
<color rgba="0.74509803921568629193 0.73725490196078435901 0.72941176470588231506 1.0"/>
</material>
</visual>
<collision>
<origin xyz="2.2204460492503130808e-16 -2.498001805406602216e-16 -0.012499999999999927836" rpy="1.5707963267948954478 -5.6398111784001782669e-16 -2.0943951023931832722" />
<geometry>
<mesh filename="package:///m5-nut-4mm.stl"/>
</geometry>
</collision>
<visual>
<origin xyz="2.7755575615628913511e-16 8.3266726846886740532e-17 0.0049800000000003452616" rpy="1.570796326794896558 1.6812141786068138525e-15 0.1301174658363873915" />
<geometry>
<mesh filename="package:///m5-washer.stl"/>
</geometry>
<material name="m5-washer_material">
<color rgba="0.74509803921568629193 0.73725490196078435901 0.72941176470588231506 1.0"/>
</material>
</visual>
<collision>
<origin xyz="2.7755575615628913511e-16 8.3266726846886740532e-17 0.0049800000000003452616" rpy="1.570796326794896558 1.6812141786068138525e-15 0.1301174658363873915" />
<geometry>
<mesh filename="package:///m5-washer.stl"/>
</geometry>
</collision>
<visual>
<origin xyz="-5.5511151231257827021e-17 -1.9428902930940239457e-16 0.021000000000000351719" rpy="1.5707963267948974462 3.2299662057370061167e-17 1.1971608400059527034e-15" />
<geometry>
<mesh filename="package:///m5-screw-cut.stl"/>
</geometry>
<material name="m5-screw-cut_material">
<color rgba="0.74901960784313725839 0.74901960784313725839 0.74901960784313725839 1.0"/>
</material>
</visual>
<collision>
<origin xyz="-5.5511151231257827021e-17 -1.9428902930940239457e-16 0.021000000000000351719" rpy="1.5707963267948974462 3.2299662057370061167e-17 1.1971608400059527034e-15" />
<geometry>
<mesh filename="package:///m5-screw-cut.stl"/>
</geometry>
</collision>
<visual>
<origin xyz="0 0 0.0049900000000003552625" rpy="-1.5707963267948943376 -2.5390773309256508855e-15 -2.0943951023931837163" />
<geometry>
<mesh filename="package:///m5-nut-4mm.stl"/>
</geometry>
<material name="m5-nut-4mm_material">
<color rgba="0.74509803921568629193 0.73725490196078435901 0.72941176470588231506 1.0"/>
</material>
</visual>
<collision>
<origin xyz="0 0 0.0049900000000003552625" rpy="-1.5707963267948943376 -2.5390773309256508855e-15 -2.0943951023931837163" />
<geometry>
<mesh filename="package:///m5-nut-4mm.stl"/>
</geometry>
</collision>
<inertial>
<origin xyz="-1.101176199127308002e-15 3.1708361649744899036e-06 0.0063296302775225901302" rpy="0 0 0"/>
<mass value="0.077205002433972699794" />
<inertia ixx="6.6468537158775889092e-05" ixy="-9.3046808547949159804e-21"  ixz="5.1702685700095563607e-19" iyy="6.6468905141631217173e-05" iyz="7.454468002234256595e-09" izz="0.00012017125669477353575" />
</inertial>
</link>

<joint name="wheel_a" type="revolute">
<origin xyz="0.1109999999999954079 5.5511151231257827021e-17 0.0080000000000000071054" rpy="1.2500110860542346747e-15 -1.544204936456279263e-15 -2.7410493356107226148" />
<parent link="lim_frame_2" />
<child link="wheel_shaft_3" />
<axis xyz="0 0 1"/>
<limit effort="1" velocity="20" />
<joint_properties friction="0.0"/>
</joint>

<link name="wheel_shaft_4">
<visual>
<origin xyz="-2.4702462297909733024e-15 3.9968028886505635455e-15 0.015999999999999930944" rpy="1.5707963267948938935 -9.4994939601877194544e-16 1.3109076122629485919e-14" />
<geometry>
<mesh filename="package:///nut-5.stl"/>
</geometry>
<material name="nut-5_material">
<color rgba="0.74509803921568629193 0.73725490196078435901 0.72941176470588231506 1.0"/>
</material>
</visual>
<collision>
<origin xyz="-2.4702462297909733024e-15 3.9968028886505635455e-15 0.015999999999999930944" rpy="1.5707963267948938935 -9.4994939601877194544e-16 1.3109076122629485919e-14" />
<geometry>
<mesh filename="package:///nut-5.stl"/>
</geometry>
</collision>
<visual>
<origin xyz="-8.3266726846886740532e-17 5.5511151231257827021e-17 0.0049799999999999566835" rpy="1.570796326794896558 1.6638082586960859222e-15 0.1301174658363871417" />
<geometry>
<mesh filename="package:///m5-washer.stl"/>
</geometry>
<material name="m5-washer_material">
<color rgba="0.74509803921568629193 0.73725490196078435901 0.72941176470588231506 1.0"/>
</material>
</visual>
<collision>
<origin xyz="-8.3266726846886740532e-17 5.5511151231257827021e-17 0.0049799999999999566835" rpy="1.570796326794896558 1.6638082586960859222e-15 0.1301174658363871417" />
<geometry>
<mesh filename="package:///m5-washer.stl"/>
</geometry>
</collision>
<visual>
<origin xyz="5.5511151231257827021e-17 0 -0.012500000000000011102" rpy="1.5707963267948954478 -5.0178384066880509059e-16 -2.0943951023931828281" />
<geometry>
<mesh filename="package:///m5-nut-4mm.stl"/>
</geometry>
<material name="m5-nut-4mm_material">
<color rgba="0.74509803921568629193 0.73725490196078435901 0.72941176470588231506 1.0"/>
</material>
</visual>
<collision>
<origin xyz="5.5511151231257827021e-17 0 -0.012500000000000011102" rpy="1.5707963267948954478 -5.0178384066880509059e-16 -2.0943951023931828281" />
<geometry>
<mesh filename="package:///m5-nut-4mm.stl"/>
</geometry>
</collision>
<visual>
<origin xyz="-2.7755575615628913511e-17 -5.5511151231257827021e-17 0.020999999999999879874" rpy="1.5707963267948974462 -4.9259401172872839869e-19 9.9610521820854086467e-16" />
<geometry>
<mesh filename="package:///m5-screw-cut.stl"/>
</geometry>
<material name="m5-screw-cut_material">
<color rgba="0.74901960784313725839 0.74901960784313725839 0.74901960784313725839 1.0"/>
</material>
</visual>
<collision>
<origin xyz="-2.7755575615628913511e-17 -5.5511151231257827021e-17 0.020999999999999879874" rpy="1.5707963267948974462 -4.9259401172872839869e-19 9.9610521820854086467e-16" />
<geometry>
<mesh filename="package:///m5-screw-cut.stl"/>
</geometry>
</collision>
<visual>
<origin xyz="-8.3266726846886740532e-17 0 0.0049899999999999666844" rpy="-1.5707963267948943376 -2.4864301093642755695e-15 -2.0943951023931828281" />
<geometry>
<mesh filename="package:///m5-nut-4mm.stl"/>
</geometry>
<material name="m5-nut-4mm_material">
<color rgba="0.74509803921568629193 0.73725490196078435901 0.72941176470588231506 1.0"/>
</material>
</visual>
<collision>
<origin xyz="-8.3266726846886740532e-17 0 0.0049899999999999666844" rpy="-1.5707963267948943376 -2.4864301093642755695e-15 -2.0943951023931828281" />
<geometry>
<mesh filename="package:///m5-nut-4mm.stl"/>
</geometry>
</collision>
<visual>
<origin xyz="-2.7755575615628913511e-17 0 -0.011500000000000010214" rpy="1.570796326794896558 1.4351745718587732033e-15 -0.02207975769648816769" />
<geometry>
<mesh filename="package:///m5-washer.stl"/>
</geometry>
<material name="m5-washer_material">
<color rgba="0.74509803921568629193 0.73725490196078435901 0.72941176470588231506 1.0"/>
</material>
</visual>
<collision>
<origin xyz="-2.7755575615628913511e-17 0 -0.011500000000000010214" rpy="1.570796326794896558 1.4351745718587732033e-15 -0.02207975769648816769" />
<geometry>
<mesh filename="package:///m5-washer.stl"/>
</geometry>
</collision>
<visual>
<origin xyz="-2.553512956637860043e-15 4.0523140398818213725e-15 0.015999999999999930944" rpy="1.5707963267948938935 -9.4994939601877194544e-16 1.3109076122629485919e-14" />
<geometry>
<mesh filename="package:///wheel.stl"/>
</geometry>
<material name="wheel_material">
<color rgba="0.21960784313725489891 0.18039215686274509554 0.12549019607843137081 1.0"/>
</material>
</visual>
<collision>
<origin xyz="-2.553512956637860043e-15 4.0523140398818213725e-15 0.015999999999999930944" rpy="1.5707963267948938935 -9.4994939601877194544e-16 1.3109076122629485919e-14" />
<geometry>
<mesh filename="package:///wheel.stl"/>
</geometry>
</collision>
<visual>
<origin xyz="-2.7755575615628913511e-17 -5.5511151231257827021e-17 0" rpy="1.570796326794896558 -1.4734914357560686431e-18 -6.0079016811698804821e-19" />
<geometry>
<mesh filename="package:///spur_gear22.stl"/>
</geometry>
<material name="spur_gear22_material">
<color rgba="0.80000000000000004441 0.80000000000000004441 0.80000000000000004441 1.0"/>
</material>
</visual>
<collision>
<origin xyz="-2.7755575615628913511e-17 -5.5511151231257827021e-17 0" rpy="1.570796326794896558 -1.4734914357560686431e-18 -6.0079016811698804821e-19" />
<geometry>
<mesh filename="package:///spur_gear22.stl"/>
</geometry>
</collision>
<inertial>
<origin xyz="-1.3275230027178224186e-15 3.1708361649311925439e-06 0.006329630277522381096" rpy="0 0 0"/>
<mass value="0.077205002433972699794" />
<inertia ixx="6.6468537158775834882e-05" ixy="-6.9866584374696418381e-21"  ixz="6.1352213855574884959e-19" iyy="6.6468905141631000333e-05" iyz="7.4544680022623608834e-09" izz="0.0001201712566947735764" />
</inertial>
</link>

<joint name="wheel_b" type="revolute">
<origin xyz="-0.11099999999999532463 2.7755575615628913511e-16 0.0079999999999999793499" rpy="1.2736879123411381812e-15 2.5288747077123325142e-15 1.8176008417319950983" />
<parent link="lim_frame_2" />
<child link="wheel_shaft_4" />
<axis xyz="0 0 1"/>
<limit effort="1" velocity="20" />
<joint_properties friction="0.0"/>
</joint>

<joint name="sun_a" type="revolute">
<origin xyz="-2.2204460492503130808e-16 0.00010468429334425932709 -0.028999999999999914735" rpy="3.1415926535897926719 -2.8669353829452643957e-16 -3.1415926535897886751" />
<parent link="assembly_3_2" />
<child link="lim_frame_2" />
<axis xyz="0 0 1"/>
<limit effort="1" velocity="20" />
<joint_properties friction="0.0"/>
</joint>

<joint name="motor_a" type="revolute">
<origin xyz="-0.31888221975469926983 0.18552361240918216478 0.25494999775085969151" rpy="-1.5607748743761082899 -9.08699813967281389e-05 -3.1234578701676607437" />
<parent link="body" />
<child link="assembly_3_2" />
<axis xyz="0 0 1"/>
<limit effort="1" velocity="20" />
<joint_properties friction="0.0"/>
</joint>


</robot>
